[2024-06-26T09:27:53.182+0000] {local_task_job_runner.py:120} INFO - ::group::Pre task execution logs
[2024-06-26T09:27:53.212+0000] {taskinstance.py:2076} INFO - Dependencies all met for dep_context=non-requeueable deps ti=<TaskInstance: coba_ds_v4.load_gbq scheduled__2024-06-25T00:00:00+00:00 [queued]>
[2024-06-26T09:27:53.220+0000] {taskinstance.py:2076} INFO - Dependencies all met for dep_context=requeueable deps ti=<TaskInstance: coba_ds_v4.load_gbq scheduled__2024-06-25T00:00:00+00:00 [queued]>
[2024-06-26T09:27:53.221+0000] {taskinstance.py:2306} INFO - Starting attempt 4 of 4
[2024-06-26T09:27:53.235+0000] {taskinstance.py:2330} INFO - Executing <Task(LoadGoogleBigQuery): load_gbq> on 2024-06-25 00:00:00+00:00
[2024-06-26T09:27:53.244+0000] {warnings.py:112} WARNING - /home/***/.local/lib/python3.12/site-packages/***/task/task_runner/standard_task_runner.py:61: DeprecationWarning: This process (pid=429) is multi-threaded, use of fork() may lead to deadlocks in the child.
  pid = os.fork()

[2024-06-26T09:27:53.246+0000] {standard_task_runner.py:63} INFO - Started process 431 to run task
[2024-06-26T09:27:53.245+0000] {standard_task_runner.py:90} INFO - Running: ['***', 'tasks', 'run', 'coba_ds_v4', 'load_gbq', 'scheduled__2024-06-25T00:00:00+00:00', '--job-id', '293', '--raw', '--subdir', 'DAGS_FOLDER/etl_dags.py', '--cfg-path', '/tmp/tmp14nqk215']
[2024-06-26T09:27:53.248+0000] {standard_task_runner.py:91} INFO - Job 293: Subtask load_gbq
[2024-06-26T09:27:53.301+0000] {task_command.py:426} INFO - Running <TaskInstance: coba_ds_v4.load_gbq scheduled__2024-06-25T00:00:00+00:00 [running]> on host 0f460bd5d17a
[2024-06-26T09:27:53.388+0000] {taskinstance.py:2648} INFO - Exporting env vars: AIRFLOW_CTX_DAG_OWNER='Kelompok 5 Capstone DE' AIRFLOW_CTX_DAG_ID='coba_ds_v4' AIRFLOW_CTX_TASK_ID='load_gbq' AIRFLOW_CTX_EXECUTION_DATE='2024-06-25T00:00:00+00:00' AIRFLOW_CTX_TRY_NUMBER='4' AIRFLOW_CTX_DAG_RUN_ID='scheduled__2024-06-25T00:00:00+00:00'
[2024-06-26T09:27:53.389+0000] {taskinstance.py:430} INFO - ::endgroup::
[2024-06-26T09:27:53.424+0000] {connection.py:274} WARNING - Connection schemes (type: google_cloud_platform) shall not contain '_' according to RFC3986.
[2024-06-26T09:27:53.427+0000] {base.py:84} INFO - Using connection ID 'gcp_conn_capstone_de' for task execution.
[2024-06-26T09:27:58.129+0000] {logging_mixin.py:188} INFO - Loaded 0 rows into capstone-de2.***_peduli_pintar_fact.fact_donation_transaction$20240625
[2024-06-26T09:28:02.653+0000] {logging_mixin.py:188} INFO - Loaded 0 rows into capstone-de2.***_peduli_pintar_fact.fact_volunteer_applications$20240625
[2024-06-26T09:28:06.573+0000] {logging_mixin.py:188} INFO - Loaded 0 rows into capstone-de2.***_peduli_pintar_fact.fact_volunteer_testimoni$20240625
[2024-06-26T09:28:10.973+0000] {logging_mixin.py:188} INFO - Loaded 0 rows into capstone-de2.***_peduli_pintar_fact.fact_article_popular$20240625
[2024-06-26T09:28:14.994+0000] {logging_mixin.py:188} INFO - Loaded 0 rows into capstone-de2.***_peduli_pintar_fact.fact_bookmark_fundraising$20240625
[2024-06-26T09:28:18.536+0000] {logging_mixin.py:188} INFO - Loaded 0 rows into capstone-de2.***_peduli_pintar_fact.fact_bookmark_volunteer_vacancies$20240625
[2024-06-26T09:28:18.987+0000] {connection.py:274} WARNING - Connection schemes (type: google_cloud_platform) shall not contain '_' according to RFC3986.
[2024-06-26T09:28:18.994+0000] {base.py:84} INFO - Using connection ID 'gcp_conn_capstone_de' for task execution.
[2024-06-26T09:28:23.767+0000] {logging_mixin.py:188} INFO - Loaded 0 rows into capstone-de2.***_peduli_pintar_dim.dim_fundraisings$20240625
[2024-06-26T09:28:24.259+0000] {taskinstance.py:441} INFO - ::group::Post task execution logs
[2024-06-26T09:28:24.267+0000] {taskinstance.py:2905} ERROR - Task failed with exception
Traceback (most recent call last):
  File "/home/airflow/.local/lib/python3.12/site-packages/google/cloud/bigquery/client.py", line 2584, in load_table_from_file
    response = self._do_multipart_upload(
               ^^^^^^^^^^^^^^^^^^^^^^^^^^
  File "/home/airflow/.local/lib/python3.12/site-packages/google/cloud/bigquery/client.py", line 3148, in _do_multipart_upload
    response = upload.transmit(
               ^^^^^^^^^^^^^^^^
  File "/home/airflow/.local/lib/python3.12/site-packages/google/resumable_media/requests/upload.py", line 153, in transmit
    return _request_helpers.wait_and_retry(
           ^^^^^^^^^^^^^^^^^^^^^^^^^^^^^^^^
  File "/home/airflow/.local/lib/python3.12/site-packages/google/resumable_media/requests/_request_helpers.py", line 155, in wait_and_retry
    response = func()
               ^^^^^^
  File "/home/airflow/.local/lib/python3.12/site-packages/google/resumable_media/requests/upload.py", line 149, in retriable_request
    self._process_response(result)
  File "/home/airflow/.local/lib/python3.12/site-packages/google/resumable_media/_upload.py", line 125, in _process_response
    _helpers.require_status_code(response, (http.client.OK,), self._get_status_code)
  File "/home/airflow/.local/lib/python3.12/site-packages/google/resumable_media/_helpers.py", line 108, in require_status_code
    raise common.InvalidResponse(
google.resumable_media.common.InvalidResponse: ('Request failed with status code', 400, 'Expected one of', 200)

During handling of the above exception, another exception occurred:

Traceback (most recent call last):
  File "/home/airflow/.local/lib/python3.12/site-packages/airflow/models/taskinstance.py", line 465, in _execute_task
    result = _execute_callable(context=context, **execute_callable_kwargs)
             ^^^^^^^^^^^^^^^^^^^^^^^^^^^^^^^^^^^^^^^^^^^^^^^^^^^^^^^^^^^^^
  File "/home/airflow/.local/lib/python3.12/site-packages/airflow/models/taskinstance.py", line 432, in _execute_callable
    return execute_callable(context=context, **execute_callable_kwargs)
           ^^^^^^^^^^^^^^^^^^^^^^^^^^^^^^^^^^^^^^^^^^^^^^^^^^^^^^^^^^^^
  File "/home/airflow/.local/lib/python3.12/site-packages/airflow/models/baseoperator.py", line 401, in wrapper
    return func(self, *args, **kwargs)
           ^^^^^^^^^^^^^^^^^^^^^^^^^^^
  File "/opt/airflow/dags/custom_operator/etl_operator.py", line 513, in execute
    self.upload_df_to_gbq(dataset_id_dim_ds, table_dim_table, ds, f"dags/data_loaded/dim/{ds}/" )
  File "/opt/airflow/dags/custom_operator/etl_operator.py", line 456, in upload_df_to_gbq
    load_job = client.load_table_from_dataframe(
               ^^^^^^^^^^^^^^^^^^^^^^^^^^^^^^^^^
  File "/home/airflow/.local/lib/python3.12/site-packages/google/cloud/bigquery/client.py", line 2824, in load_table_from_dataframe
    return self.load_table_from_file(
           ^^^^^^^^^^^^^^^^^^^^^^^^^^
  File "/home/airflow/.local/lib/python3.12/site-packages/google/cloud/bigquery/client.py", line 2588, in load_table_from_file
    raise exceptions.from_http_response(exc.response)
google.api_core.exceptions.BadRequest: 400 POST https://bigquery.googleapis.com/upload/bigquery/v2/projects/capstone-de2/jobs?uploadType=multipart: Provided Schema does not match Table capstone-de2:airflow_peduli_pintar_dim.dim_fundraisings$20240625. Cannot add fields (field: amount)
[2024-06-26T09:28:24.369+0000] {taskinstance.py:1206} INFO - Marking task as FAILED. dag_id=coba_ds_v4, task_id=load_gbq, run_id=scheduled__2024-06-25T00:00:00+00:00, execution_date=20240625T000000, start_date=20240626T092753, end_date=20240626T092824
[2024-06-26T09:28:24.444+0000] {standard_task_runner.py:110} ERROR - Failed to execute job 293 for task load_gbq (400 POST https://bigquery.googleapis.com/upload/bigquery/v2/projects/capstone-de2/jobs?uploadType=multipart: Provided Schema does not match Table capstone-de2:airflow_peduli_pintar_dim.dim_fundraisings$20240625. Cannot add fields (field: amount); 431)
[2024-06-26T09:28:24.534+0000] {local_task_job_runner.py:240} INFO - Task exited with return code 1
[2024-06-26T09:28:24.609+0000] {taskinstance.py:3503} INFO - 0 downstream tasks scheduled from follow-on schedule check
[2024-06-26T09:28:24.613+0000] {local_task_job_runner.py:222} INFO - ::endgroup::
