[2024-06-26T14:09:09.108+0000] {local_task_job_runner.py:120} INFO - ::group::Pre task execution logs
[2024-06-26T14:09:09.137+0000] {taskinstance.py:2076} INFO - Dependencies all met for dep_context=non-requeueable deps ti=<TaskInstance: peduli_pintar_elt_all_dags_v1.load_gbq scheduled__2024-06-24T00:00:00+00:00 [queued]>
[2024-06-26T14:09:09.150+0000] {taskinstance.py:2076} INFO - Dependencies all met for dep_context=requeueable deps ti=<TaskInstance: peduli_pintar_elt_all_dags_v1.load_gbq scheduled__2024-06-24T00:00:00+00:00 [queued]>
[2024-06-26T14:09:09.151+0000] {taskinstance.py:2306} INFO - Starting attempt 1 of 5
[2024-06-26T14:09:09.176+0000] {taskinstance.py:2330} INFO - Executing <Task(LoadGoogleBigQuery): load_gbq> on 2024-06-24 00:00:00+00:00
[2024-06-26T14:09:09.189+0000] {warnings.py:112} WARNING - /home/***/.local/lib/python3.12/site-packages/***/task/task_runner/standard_task_runner.py:61: DeprecationWarning: This process (pid=212) is multi-threaded, use of fork() may lead to deadlocks in the child.
  pid = os.fork()

[2024-06-26T14:09:09.192+0000] {standard_task_runner.py:63} INFO - Started process 223 to run task
[2024-06-26T14:09:09.192+0000] {standard_task_runner.py:90} INFO - Running: ['***', 'tasks', 'run', 'peduli_pintar_elt_all_dags_v1', 'load_gbq', 'scheduled__2024-06-24T00:00:00+00:00', '--job-id', '19', '--raw', '--subdir', 'DAGS_FOLDER/etl_all_dags.py', '--cfg-path', '/tmp/tmpz4m83yqo']
[2024-06-26T14:09:09.198+0000] {standard_task_runner.py:91} INFO - Job 19: Subtask load_gbq
[2024-06-26T14:09:09.296+0000] {task_command.py:426} INFO - Running <TaskInstance: peduli_pintar_elt_all_dags_v1.load_gbq scheduled__2024-06-24T00:00:00+00:00 [running]> on host 7ecff3f83b62
[2024-06-26T14:09:09.801+0000] {taskinstance.py:2648} INFO - Exporting env vars: AIRFLOW_CTX_DAG_OWNER='Kelompok 5 Capstone DE' AIRFLOW_CTX_DAG_ID='peduli_pintar_elt_all_dags_v1' AIRFLOW_CTX_TASK_ID='load_gbq' AIRFLOW_CTX_EXECUTION_DATE='2024-06-24T00:00:00+00:00' AIRFLOW_CTX_TRY_NUMBER='1' AIRFLOW_CTX_DAG_RUN_ID='scheduled__2024-06-24T00:00:00+00:00'
[2024-06-26T14:09:09.838+0000] {taskinstance.py:430} INFO - ::endgroup::
[2024-06-26T14:09:10.850+0000] {connection.py:274} WARNING - Connection schemes (type: google_cloud_platform) shall not contain '_' according to RFC3986.
[2024-06-26T14:09:10.858+0000] {base.py:84} INFO - Using connection ID 'gcp_conn_capstone_de' for task execution.
[2024-06-26T14:09:49.121+0000] {logging_mixin.py:188} INFO - Loaded 105 rows and 9 columns to ***_peduli_pintar_fact_all.fact_donation_transaction
[2024-06-26T14:09:49.276+0000] {connection.py:274} WARNING - Connection schemes (type: google_cloud_platform) shall not contain '_' according to RFC3986.
[2024-06-26T14:09:49.280+0000] {base.py:84} INFO - Using connection ID 'gcp_conn_capstone_de' for task execution.
[2024-06-26T14:09:57.400+0000] {logging_mixin.py:188} INFO - Loaded 133 rows and 6 columns to ***_peduli_pintar_fact_all.fact_volunteer_applications
[2024-06-26T14:09:57.409+0000] {connection.py:274} WARNING - Connection schemes (type: google_cloud_platform) shall not contain '_' according to RFC3986.
[2024-06-26T14:09:57.410+0000] {base.py:84} INFO - Using connection ID 'gcp_conn_capstone_de' for task execution.
[2024-06-26T14:10:05.104+0000] {logging_mixin.py:188} INFO - Loaded 31 rows and 6 columns to ***_peduli_pintar_fact_all.fact_volunteer_testimoni
[2024-06-26T14:10:05.115+0000] {connection.py:274} WARNING - Connection schemes (type: google_cloud_platform) shall not contain '_' according to RFC3986.
[2024-06-26T14:10:05.116+0000] {base.py:84} INFO - Using connection ID 'gcp_conn_capstone_de' for task execution.
[2024-06-26T14:10:11.177+0000] {logging_mixin.py:188} INFO - Loaded 60 rows and 7 columns to ***_peduli_pintar_fact_all.fact_article_popular
[2024-06-26T14:10:11.185+0000] {connection.py:274} WARNING - Connection schemes (type: google_cloud_platform) shall not contain '_' according to RFC3986.
[2024-06-26T14:10:11.186+0000] {base.py:84} INFO - Using connection ID 'gcp_conn_capstone_de' for task execution.
[2024-06-26T14:10:19.527+0000] {logging_mixin.py:188} INFO - Loaded 46 rows and 5 columns to ***_peduli_pintar_fact_all.fact_bookmark_fundraising
[2024-06-26T14:10:19.541+0000] {connection.py:274} WARNING - Connection schemes (type: google_cloud_platform) shall not contain '_' according to RFC3986.
[2024-06-26T14:10:19.544+0000] {base.py:84} INFO - Using connection ID 'gcp_conn_capstone_de' for task execution.
[2024-06-26T14:10:25.688+0000] {logging_mixin.py:188} INFO - Loaded 42 rows and 5 columns to ***_peduli_pintar_fact_all.fact_bookmark_volunteer_vacancies
[2024-06-26T14:10:25.701+0000] {connection.py:274} WARNING - Connection schemes (type: google_cloud_platform) shall not contain '_' according to RFC3986.
[2024-06-26T14:10:25.702+0000] {base.py:84} INFO - Using connection ID 'gcp_conn_capstone_de' for task execution.
[2024-06-26T14:10:33.149+0000] {logging_mixin.py:188} INFO - Loaded 35 rows and 11 columns to ***_peduli_pintar_dim_all.dim_fundraisings
[2024-06-26T14:10:33.158+0000] {connection.py:274} WARNING - Connection schemes (type: google_cloud_platform) shall not contain '_' according to RFC3986.
[2024-06-26T14:10:33.159+0000] {base.py:84} INFO - Using connection ID 'gcp_conn_capstone_de' for task execution.
[2024-06-26T14:10:39.120+0000] {logging_mixin.py:188} INFO - Loaded 4 rows and 3 columns to ***_peduli_pintar_dim_all.dim_fundraising_categories
[2024-06-26T14:10:39.129+0000] {connection.py:274} WARNING - Connection schemes (type: google_cloud_platform) shall not contain '_' according to RFC3986.
[2024-06-26T14:10:39.131+0000] {base.py:84} INFO - Using connection ID 'gcp_conn_capstone_de' for task execution.
[2024-06-26T14:10:46.015+0000] {logging_mixin.py:188} INFO - Loaded 196 rows and 6 columns to ***_peduli_pintar_dim_all.dim_donation_manual
[2024-06-26T14:10:46.024+0000] {connection.py:274} WARNING - Connection schemes (type: google_cloud_platform) shall not contain '_' according to RFC3986.
[2024-06-26T14:10:46.025+0000] {base.py:84} INFO - Using connection ID 'gcp_conn_capstone_de' for task execution.
[2024-06-26T14:10:54.001+0000] {logging_mixin.py:188} INFO - Loaded 15 rows and 11 columns to ***_peduli_pintar_dim_all.dim_organization
[2024-06-26T14:10:54.014+0000] {connection.py:274} WARNING - Connection schemes (type: google_cloud_platform) shall not contain '_' according to RFC3986.
[2024-06-26T14:10:54.016+0000] {base.py:84} INFO - Using connection ID 'gcp_conn_capstone_de' for task execution.
[2024-06-26T14:11:31.883+0000] {job.py:218} ERROR - Job heartbeat got an exception
Traceback (most recent call last):
  File "/home/airflow/.local/lib/python3.12/site-packages/sqlalchemy/engine/base.py", line 3371, in _wrap_pool_connect
    return fn()
           ^^^^
  File "/home/airflow/.local/lib/python3.12/site-packages/sqlalchemy/pool/base.py", line 327, in connect
    return _ConnectionFairy._checkout(self)
           ^^^^^^^^^^^^^^^^^^^^^^^^^^^^^^^^
  File "/home/airflow/.local/lib/python3.12/site-packages/sqlalchemy/pool/base.py", line 894, in _checkout
    fairy = _ConnectionRecord.checkout(pool)
            ^^^^^^^^^^^^^^^^^^^^^^^^^^^^^^^^
  File "/home/airflow/.local/lib/python3.12/site-packages/sqlalchemy/pool/base.py", line 493, in checkout
    rec = pool._do_get()
          ^^^^^^^^^^^^^^
  File "/home/airflow/.local/lib/python3.12/site-packages/sqlalchemy/pool/impl.py", line 256, in _do_get
    return self._create_connection()
           ^^^^^^^^^^^^^^^^^^^^^^^^^
  File "/home/airflow/.local/lib/python3.12/site-packages/sqlalchemy/pool/base.py", line 273, in _create_connection
    return _ConnectionRecord(self)
           ^^^^^^^^^^^^^^^^^^^^^^^
  File "/home/airflow/.local/lib/python3.12/site-packages/sqlalchemy/pool/base.py", line 388, in __init__
    self.__connect()
  File "/home/airflow/.local/lib/python3.12/site-packages/sqlalchemy/pool/base.py", line 690, in __connect
    with util.safe_reraise():
  File "/home/airflow/.local/lib/python3.12/site-packages/sqlalchemy/util/langhelpers.py", line 70, in __exit__
    compat.raise_(
  File "/home/airflow/.local/lib/python3.12/site-packages/sqlalchemy/util/compat.py", line 211, in raise_
    raise exception
  File "/home/airflow/.local/lib/python3.12/site-packages/sqlalchemy/pool/base.py", line 686, in __connect
    self.dbapi_connection = connection = pool._invoke_creator(self)
                                         ^^^^^^^^^^^^^^^^^^^^^^^^^^
  File "/home/airflow/.local/lib/python3.12/site-packages/sqlalchemy/engine/create.py", line 574, in connect
    return dialect.connect(*cargs, **cparams)
           ^^^^^^^^^^^^^^^^^^^^^^^^^^^^^^^^^^
  File "/home/airflow/.local/lib/python3.12/site-packages/sqlalchemy/engine/default.py", line 598, in connect
    return self.dbapi.connect(*cargs, **cparams)
           ^^^^^^^^^^^^^^^^^^^^^^^^^^^^^^^^^^^^^
  File "/home/airflow/.local/lib/python3.12/site-packages/psycopg2/__init__.py", line 122, in connect
    conn = _connect(dsn, connection_factory=connection_factory, **kwasync)
           ^^^^^^^^^^^^^^^^^^^^^^^^^^^^^^^^^^^^^^^^^^^^^^^^^^^^^^^^^^^^^^^
psycopg2.OperationalError: could not translate host name "postgres" to address: Temporary failure in name resolution


The above exception was the direct cause of the following exception:

Traceback (most recent call last):
  File "/home/airflow/.local/lib/python3.12/site-packages/airflow/jobs/job.py", line 192, in heartbeat
    self._merge_from(Job._fetch_from_db(self, session))
                     ^^^^^^^^^^^^^^^^^^^^^^^^^^^^^^^^^
  File "/home/airflow/.local/lib/python3.12/site-packages/airflow/api_internal/internal_api_call.py", line 115, in wrapper
    return func(*args, **kwargs)
           ^^^^^^^^^^^^^^^^^^^^^
  File "/home/airflow/.local/lib/python3.12/site-packages/airflow/utils/session.py", line 76, in wrapper
    return func(*args, **kwargs)
           ^^^^^^^^^^^^^^^^^^^^^
  File "/home/airflow/.local/lib/python3.12/site-packages/airflow/utils/retries.py", line 89, in wrapped_function
    for attempt in run_with_db_retries(max_retries=retries, logger=logger, **retry_kwargs):
  File "/home/airflow/.local/lib/python3.12/site-packages/tenacity/__init__.py", line 435, in __iter__
    do = self.iter(retry_state=retry_state)
         ^^^^^^^^^^^^^^^^^^^^^^^^^^^^^^^^^^
  File "/home/airflow/.local/lib/python3.12/site-packages/tenacity/__init__.py", line 368, in iter
    result = action(retry_state)
             ^^^^^^^^^^^^^^^^^^^
  File "/home/airflow/.local/lib/python3.12/site-packages/tenacity/__init__.py", line 410, in exc_check
    raise retry_exc.reraise()
          ^^^^^^^^^^^^^^^^^^^
  File "/home/airflow/.local/lib/python3.12/site-packages/tenacity/__init__.py", line 183, in reraise
    raise self.last_attempt.result()
          ^^^^^^^^^^^^^^^^^^^^^^^^^^
  File "/usr/local/lib/python3.12/concurrent/futures/_base.py", line 449, in result
    return self.__get_result()
           ^^^^^^^^^^^^^^^^^^^
  File "/usr/local/lib/python3.12/concurrent/futures/_base.py", line 401, in __get_result
    raise self._exception
  File "/home/airflow/.local/lib/python3.12/site-packages/airflow/utils/retries.py", line 98, in wrapped_function
    return func(*args, **kwargs)
           ^^^^^^^^^^^^^^^^^^^^^
  File "/home/airflow/.local/lib/python3.12/site-packages/airflow/jobs/job.py", line 316, in _fetch_from_db
    session.merge(job)
  File "/home/airflow/.local/lib/python3.12/site-packages/sqlalchemy/orm/session.py", line 3056, in merge
    return self._merge(
           ^^^^^^^^^^^^
  File "/home/airflow/.local/lib/python3.12/site-packages/sqlalchemy/orm/session.py", line 3136, in _merge
    merged = self.get(
             ^^^^^^^^^
  File "/home/airflow/.local/lib/python3.12/site-packages/sqlalchemy/orm/session.py", line 2853, in get
    return self._get_impl(
           ^^^^^^^^^^^^^^^
  File "/home/airflow/.local/lib/python3.12/site-packages/sqlalchemy/orm/session.py", line 2975, in _get_impl
    return db_load_fn(
           ^^^^^^^^^^^
  File "/home/airflow/.local/lib/python3.12/site-packages/sqlalchemy/orm/loading.py", line 530, in load_on_pk_identity
    session.execute(
  File "/home/airflow/.local/lib/python3.12/site-packages/sqlalchemy/orm/session.py", line 1716, in execute
    conn = self._connection_for_bind(bind)
           ^^^^^^^^^^^^^^^^^^^^^^^^^^^^^^^
  File "/home/airflow/.local/lib/python3.12/site-packages/sqlalchemy/orm/session.py", line 1555, in _connection_for_bind
    return self._transaction._connection_for_bind(
           ^^^^^^^^^^^^^^^^^^^^^^^^^^^^^^^^^^^^^^^
  File "/home/airflow/.local/lib/python3.12/site-packages/sqlalchemy/orm/session.py", line 750, in _connection_for_bind
    conn = bind.connect()
           ^^^^^^^^^^^^^^
  File "/home/airflow/.local/lib/python3.12/site-packages/sqlalchemy/future/engine.py", line 412, in connect
    return super(Engine, self).connect()
           ^^^^^^^^^^^^^^^^^^^^^^^^^^^^^
  File "/home/airflow/.local/lib/python3.12/site-packages/sqlalchemy/engine/base.py", line 3325, in connect
    return self._connection_cls(self, close_with_result=close_with_result)
           ^^^^^^^^^^^^^^^^^^^^^^^^^^^^^^^^^^^^^^^^^^^^^^^^^^^^^^^^^^^^^^^
  File "/home/airflow/.local/lib/python3.12/site-packages/sqlalchemy/engine/base.py", line 96, in __init__
    else engine.raw_connection()
         ^^^^^^^^^^^^^^^^^^^^^^^
  File "/home/airflow/.local/lib/python3.12/site-packages/sqlalchemy/engine/base.py", line 3404, in raw_connection
    return self._wrap_pool_connect(self.pool.connect, _connection)
           ^^^^^^^^^^^^^^^^^^^^^^^^^^^^^^^^^^^^^^^^^^^^^^^^^^^^^^^
  File "/home/airflow/.local/lib/python3.12/site-packages/sqlalchemy/engine/base.py", line 3374, in _wrap_pool_connect
    Connection._handle_dbapi_exception_noconnection(
  File "/home/airflow/.local/lib/python3.12/site-packages/sqlalchemy/engine/base.py", line 2208, in _handle_dbapi_exception_noconnection
    util.raise_(
  File "/home/airflow/.local/lib/python3.12/site-packages/sqlalchemy/util/compat.py", line 211, in raise_
    raise exception
  File "/home/airflow/.local/lib/python3.12/site-packages/sqlalchemy/engine/base.py", line 3371, in _wrap_pool_connect
    return fn()
           ^^^^
  File "/home/airflow/.local/lib/python3.12/site-packages/sqlalchemy/pool/base.py", line 327, in connect
    return _ConnectionFairy._checkout(self)
           ^^^^^^^^^^^^^^^^^^^^^^^^^^^^^^^^
  File "/home/airflow/.local/lib/python3.12/site-packages/sqlalchemy/pool/base.py", line 894, in _checkout
    fairy = _ConnectionRecord.checkout(pool)
            ^^^^^^^^^^^^^^^^^^^^^^^^^^^^^^^^
  File "/home/airflow/.local/lib/python3.12/site-packages/sqlalchemy/pool/base.py", line 493, in checkout
    rec = pool._do_get()
          ^^^^^^^^^^^^^^
  File "/home/airflow/.local/lib/python3.12/site-packages/sqlalchemy/pool/impl.py", line 256, in _do_get
    return self._create_connection()
           ^^^^^^^^^^^^^^^^^^^^^^^^^
  File "/home/airflow/.local/lib/python3.12/site-packages/sqlalchemy/pool/base.py", line 273, in _create_connection
    return _ConnectionRecord(self)
           ^^^^^^^^^^^^^^^^^^^^^^^
  File "/home/airflow/.local/lib/python3.12/site-packages/sqlalchemy/pool/base.py", line 388, in __init__
    self.__connect()
  File "/home/airflow/.local/lib/python3.12/site-packages/sqlalchemy/pool/base.py", line 690, in __connect
    with util.safe_reraise():
  File "/home/airflow/.local/lib/python3.12/site-packages/sqlalchemy/util/langhelpers.py", line 70, in __exit__
    compat.raise_(
  File "/home/airflow/.local/lib/python3.12/site-packages/sqlalchemy/util/compat.py", line 211, in raise_
    raise exception
  File "/home/airflow/.local/lib/python3.12/site-packages/sqlalchemy/pool/base.py", line 686, in __connect
    self.dbapi_connection = connection = pool._invoke_creator(self)
                                         ^^^^^^^^^^^^^^^^^^^^^^^^^^
  File "/home/airflow/.local/lib/python3.12/site-packages/sqlalchemy/engine/create.py", line 574, in connect
    return dialect.connect(*cargs, **cparams)
           ^^^^^^^^^^^^^^^^^^^^^^^^^^^^^^^^^^
  File "/home/airflow/.local/lib/python3.12/site-packages/sqlalchemy/engine/default.py", line 598, in connect
    return self.dbapi.connect(*cargs, **cparams)
           ^^^^^^^^^^^^^^^^^^^^^^^^^^^^^^^^^^^^^
  File "/home/airflow/.local/lib/python3.12/site-packages/psycopg2/__init__.py", line 122, in connect
    conn = _connect(dsn, connection_factory=connection_factory, **kwasync)
           ^^^^^^^^^^^^^^^^^^^^^^^^^^^^^^^^^^^^^^^^^^^^^^^^^^^^^^^^^^^^^^^
sqlalchemy.exc.OperationalError: (psycopg2.OperationalError) could not translate host name "postgres" to address: Temporary failure in name resolution

(Background on this error at: https://sqlalche.me/e/14/e3q8)
[2024-06-26T14:11:32.203+0000] {job.py:226} ERROR - Job heartbeat failed with error. Scheduler is in unhealthy state
[2024-06-26T14:11:32.792+0000] {logging_mixin.py:188} INFO - Loaded 132 rows and 11 columns to ***_peduli_pintar_dim_all.dim_user
[2024-06-26T14:11:34.510+0000] {connection.py:274} WARNING - Connection schemes (type: google_cloud_platform) shall not contain '_' according to RFC3986.
[2024-06-26T14:11:34.537+0000] {base.py:84} INFO - Using connection ID 'gcp_conn_capstone_de' for task execution.
[2024-06-26T14:11:44.654+0000] {logging_mixin.py:188} INFO - Loaded 133 rows and 8 columns to ***_peduli_pintar_dim_all.dim_volunteer_applictaion
[2024-06-26T14:11:44.664+0000] {connection.py:274} WARNING - Connection schemes (type: google_cloud_platform) shall not contain '_' according to RFC3986.
[2024-06-26T14:11:44.665+0000] {base.py:84} INFO - Using connection ID 'gcp_conn_capstone_de' for task execution.
[2024-06-26T14:11:51.176+0000] {logging_mixin.py:188} INFO - Loaded 22 rows and 14 columns to ***_peduli_pintar_dim_all.dim_volunteer_vacancies
[2024-06-26T14:11:51.182+0000] {connection.py:274} WARNING - Connection schemes (type: google_cloud_platform) shall not contain '_' according to RFC3986.
[2024-06-26T14:11:51.183+0000] {base.py:84} INFO - Using connection ID 'gcp_conn_capstone_de' for task execution.
[2024-06-26T14:11:57.257+0000] {logging_mixin.py:188} INFO - Loaded 31 rows and 5 columns to ***_peduli_pintar_dim_all.dim_testimoni_volunteer
[2024-06-26T14:11:57.272+0000] {connection.py:274} WARNING - Connection schemes (type: google_cloud_platform) shall not contain '_' according to RFC3986.
[2024-06-26T14:11:57.275+0000] {base.py:84} INFO - Using connection ID 'gcp_conn_capstone_de' for task execution.
[2024-06-26T14:12:16.974+0000] {logging_mixin.py:188} INFO - Loaded 28 rows and 7 columns to ***_peduli_pintar_dim_all.dim_article
[2024-06-26T14:12:17.001+0000] {connection.py:274} WARNING - Connection schemes (type: google_cloud_platform) shall not contain '_' according to RFC3986.
[2024-06-26T14:12:17.004+0000] {base.py:84} INFO - Using connection ID 'gcp_conn_capstone_de' for task execution.
[2024-06-26T14:12:23.668+0000] {logging_mixin.py:188} INFO - Loaded 46 rows and 3 columns to ***_peduli_pintar_dim_all.dim_bookmark_fundraising
[2024-06-26T14:12:23.681+0000] {connection.py:274} WARNING - Connection schemes (type: google_cloud_platform) shall not contain '_' according to RFC3986.
[2024-06-26T14:12:23.684+0000] {base.py:84} INFO - Using connection ID 'gcp_conn_capstone_de' for task execution.
[2024-06-26T14:12:30.815+0000] {logging_mixin.py:188} INFO - Loaded 42 rows and 3 columns to ***_peduli_pintar_dim_all.dim_bookmark_volunter_vacancies
[2024-06-26T14:12:30.824+0000] {connection.py:274} WARNING - Connection schemes (type: google_cloud_platform) shall not contain '_' according to RFC3986.
[2024-06-26T14:12:30.825+0000] {base.py:84} INFO - Using connection ID 'gcp_conn_capstone_de' for task execution.
[2024-06-26T14:12:38.403+0000] {logging_mixin.py:188} INFO - Loaded 60 rows and 3 columns to ***_peduli_pintar_dim_all.dim_bookmark_article
[2024-06-26T14:12:38.410+0000] {connection.py:274} WARNING - Connection schemes (type: google_cloud_platform) shall not contain '_' according to RFC3986.
[2024-06-26T14:12:38.411+0000] {base.py:84} INFO - Using connection ID 'gcp_conn_capstone_de' for task execution.
[2024-06-26T14:12:45.634+0000] {logging_mixin.py:188} INFO - Loaded 55 rows and 5 columns to ***_peduli_pintar_dim_all.dim_comments
[2024-06-26T14:12:45.641+0000] {connection.py:274} WARNING - Connection schemes (type: google_cloud_platform) shall not contain '_' according to RFC3986.
[2024-06-26T14:12:45.642+0000] {base.py:84} INFO - Using connection ID 'gcp_conn_capstone_de' for task execution.
[2024-06-26T14:12:52.378+0000] {logging_mixin.py:188} INFO - Loaded 107 rows and 3 columns to ***_peduli_pintar_dim_all.dim_like_comments
[2024-06-26T14:12:52.383+0000] {taskinstance.py:441} INFO - ::group::Post task execution logs
[2024-06-26T14:12:52.572+0000] {taskinstance.py:1206} INFO - Marking task as SUCCESS. dag_id=peduli_pintar_elt_all_dags_v1, task_id=load_gbq, run_id=scheduled__2024-06-24T00:00:00+00:00, execution_date=20240624T000000, start_date=20240626T140909, end_date=20240626T141252
[2024-06-26T14:12:52.710+0000] {local_task_job_runner.py:240} INFO - Task exited with return code 0
[2024-06-26T14:12:52.829+0000] {taskinstance.py:3503} INFO - 0 downstream tasks scheduled from follow-on schedule check
[2024-06-26T14:12:52.832+0000] {local_task_job_runner.py:222} INFO - ::endgroup::
