[2024-06-23T14:55:44.995+0000] {local_task_job_runner.py:120} INFO - ::group::Pre task execution logs
[2024-06-23T14:55:45.048+0000] {taskinstance.py:2076} INFO - Dependencies all met for dep_context=non-requeueable deps ti=<TaskInstance: etl_all_dags_v1.load_firebase scheduled__2024-06-21T00:00:00+00:00 [queued]>
[2024-06-23T14:55:45.061+0000] {taskinstance.py:2076} INFO - Dependencies all met for dep_context=requeueable deps ti=<TaskInstance: etl_all_dags_v1.load_firebase scheduled__2024-06-21T00:00:00+00:00 [queued]>
[2024-06-23T14:55:45.062+0000] {taskinstance.py:2306} INFO - Starting attempt 1 of 3
[2024-06-23T14:55:45.092+0000] {taskinstance.py:2330} INFO - Executing <Task(LoadFirebase): load_firebase> on 2024-06-21 00:00:00+00:00
[2024-06-23T14:55:45.106+0000] {warnings.py:112} WARNING - /home/***/.local/lib/python3.12/site-packages/***/task/task_runner/standard_task_runner.py:61: DeprecationWarning: This process (pid=146) is multi-threaded, use of fork() may lead to deadlocks in the child.
  pid = os.fork()

[2024-06-23T14:55:45.109+0000] {standard_task_runner.py:63} INFO - Started process 150 to run task
[2024-06-23T14:55:45.110+0000] {standard_task_runner.py:90} INFO - Running: ['***', 'tasks', 'run', 'etl_all_dags_v1', 'load_firebase', 'scheduled__2024-06-21T00:00:00+00:00', '--job-id', '65', '--raw', '--subdir', 'DAGS_FOLDER/etl_all_dags.py', '--cfg-path', '/tmp/tmp229t07pu']
[2024-06-23T14:55:45.114+0000] {standard_task_runner.py:91} INFO - Job 65: Subtask load_firebase
[2024-06-23T14:55:45.191+0000] {task_command.py:426} INFO - Running <TaskInstance: etl_all_dags_v1.load_firebase scheduled__2024-06-21T00:00:00+00:00 [running]> on host d707524566e3
[2024-06-23T14:55:45.318+0000] {taskinstance.py:2648} INFO - Exporting env vars: AIRFLOW_CTX_DAG_OWNER='Kelompok 5 Capstone DE' AIRFLOW_CTX_DAG_ID='etl_all_dags_v1' AIRFLOW_CTX_TASK_ID='load_firebase' AIRFLOW_CTX_EXECUTION_DATE='2024-06-21T00:00:00+00:00' AIRFLOW_CTX_TRY_NUMBER='1' AIRFLOW_CTX_DAG_RUN_ID='scheduled__2024-06-21T00:00:00+00:00'
[2024-06-23T14:55:45.321+0000] {taskinstance.py:430} INFO - ::endgroup::
[2024-06-23T14:55:46.997+0000] {logging_mixin.py:188} INFO - Folder '20240621' created successfully.
[2024-06-23T14:55:47.565+0000] {logging_mixin.py:188} INFO - Dataframe admin_notifications uploaded successfully as 20240621_admin_notifications.csv!
[2024-06-23T14:55:47.975+0000] {logging_mixin.py:188} INFO - Dataframe admins uploaded successfully as 20240621_admins.csv!
[2024-06-23T14:55:48.558+0000] {logging_mixin.py:188} INFO - Dataframe applications uploaded successfully as 20240621_applications.csv!
[2024-06-23T14:55:49.058+0000] {logging_mixin.py:188} INFO - Dataframe articles uploaded successfully as 20240621_articles.csv!
[2024-06-23T14:55:49.512+0000] {logging_mixin.py:188} INFO - Dataframe comments uploaded successfully as 20240621_comments.csv!
[2024-06-23T14:55:49.940+0000] {logging_mixin.py:188} INFO - Dataframe donation_comments uploaded successfully as 20240621_donation_comments.csv!
[2024-06-23T14:55:50.472+0000] {logging_mixin.py:188} INFO - Dataframe donation_manual_comments uploaded successfully as 20240621_donation_manual_comments.csv!
[2024-06-23T14:55:51.175+0000] {logging_mixin.py:188} INFO - Dataframe donation_manuals uploaded successfully as 20240621_donation_manuals.csv!
[2024-06-23T14:55:51.656+0000] {logging_mixin.py:188} INFO - Dataframe donations uploaded successfully as 20240621_donations.csv!
[2024-06-23T14:55:52.145+0000] {logging_mixin.py:188} INFO - Dataframe fundraising_categories uploaded successfully as 20240621_fundraising_categories.csv!
[2024-06-23T14:55:52.954+0000] {logging_mixin.py:188} INFO - Dataframe fundraisings uploaded successfully as 20240621_fundraisings.csv!
[2024-06-23T15:01:11.837+0000] {taskinstance.py:441} INFO - ::group::Post task execution logs
[2024-06-23T15:01:13.923+0000] {taskinstance.py:2905} ERROR - Task failed with exception
Traceback (most recent call last):
  File "/home/airflow/.local/lib/python3.12/site-packages/urllib3/connectionpool.py", line 537, in _make_request
    response = conn.getresponse()
               ^^^^^^^^^^^^^^^^^^
  File "/home/airflow/.local/lib/python3.12/site-packages/urllib3/connection.py", line 466, in getresponse
    httplib_response = super().getresponse()
                       ^^^^^^^^^^^^^^^^^^^^^
  File "/usr/local/lib/python3.12/http/client.py", line 1428, in getresponse
    response.begin()
  File "/usr/local/lib/python3.12/http/client.py", line 331, in begin
    version, status, reason = self._read_status()
                              ^^^^^^^^^^^^^^^^^^^
  File "/usr/local/lib/python3.12/http/client.py", line 292, in _read_status
    line = str(self.fp.readline(_MAXLINE + 1), "iso-8859-1")
               ^^^^^^^^^^^^^^^^^^^^^^^^^^^^^^
  File "/usr/local/lib/python3.12/socket.py", line 708, in readinto
    return self._sock.recv_into(b)
           ^^^^^^^^^^^^^^^^^^^^^^^
  File "/usr/local/lib/python3.12/ssl.py", line 1252, in recv_into
    return self.read(nbytes, buffer)
           ^^^^^^^^^^^^^^^^^^^^^^^^^
  File "/usr/local/lib/python3.12/ssl.py", line 1104, in read
    return self._sslobj.read(len, buffer)
           ^^^^^^^^^^^^^^^^^^^^^^^^^^^^^^
TimeoutError: The read operation timed out

The above exception was the direct cause of the following exception:

Traceback (most recent call last):
  File "/home/airflow/.local/lib/python3.12/site-packages/requests/adapters.py", line 486, in send
    resp = conn.urlopen(
           ^^^^^^^^^^^^^
  File "/home/airflow/.local/lib/python3.12/site-packages/urllib3/connectionpool.py", line 847, in urlopen
    retries = retries.increment(
              ^^^^^^^^^^^^^^^^^^
  File "/home/airflow/.local/lib/python3.12/site-packages/urllib3/util/retry.py", line 470, in increment
    raise reraise(type(error), error, _stacktrace)
          ^^^^^^^^^^^^^^^^^^^^^^^^^^^^^^^^^^^^^^^^
  File "/home/airflow/.local/lib/python3.12/site-packages/urllib3/util/util.py", line 39, in reraise
    raise value
  File "/home/airflow/.local/lib/python3.12/site-packages/urllib3/connectionpool.py", line 793, in urlopen
    response = self._make_request(
               ^^^^^^^^^^^^^^^^^^^
  File "/home/airflow/.local/lib/python3.12/site-packages/urllib3/connectionpool.py", line 539, in _make_request
    self._raise_timeout(err=e, url=url, timeout_value=read_timeout)
  File "/home/airflow/.local/lib/python3.12/site-packages/urllib3/connectionpool.py", line 370, in _raise_timeout
    raise ReadTimeoutError(
urllib3.exceptions.ReadTimeoutError: HTTPSConnectionPool(host='storage.googleapis.com', port=443): Read timed out. (read timeout=60)

During handling of the above exception, another exception occurred:

Traceback (most recent call last):
  File "/home/airflow/.local/lib/python3.12/site-packages/airflow/models/taskinstance.py", line 465, in _execute_task
    result = _execute_callable(context=context, **execute_callable_kwargs)
             ^^^^^^^^^^^^^^^^^^^^^^^^^^^^^^^^^^^^^^^^^^^^^^^^^^^^^^^^^^^^^
  File "/home/airflow/.local/lib/python3.12/site-packages/airflow/models/taskinstance.py", line 432, in _execute_callable
    return execute_callable(context=context, **execute_callable_kwargs)
           ^^^^^^^^^^^^^^^^^^^^^^^^^^^^^^^^^^^^^^^^^^^^^^^^^^^^^^^^^^^^
  File "/home/airflow/.local/lib/python3.12/site-packages/airflow/models/baseoperator.py", line 401, in wrapper
    return func(self, *args, **kwargs)
           ^^^^^^^^^^^^^^^^^^^^^^^^^^^
  File "/opt/airflow/dags/custom_operator/etl_all_operator.py", line 314, in execute
    self.upload_files_to_firebase("/opt/airflow/.env", dataframes, tables_name, ds)
  File "/opt/airflow/dags/custom_operator/etl_all_operator.py", line 307, in upload_files_to_firebase
    file_ref.upload_from_string(csv_str, content_type='text/csv')
  File "/home/airflow/.local/lib/python3.12/site-packages/google/cloud/storage/blob.py", line 3089, in upload_from_string
    self.upload_from_file(
  File "/home/airflow/.local/lib/python3.12/site-packages/google/cloud/storage/blob.py", line 2796, in upload_from_file
    self._prep_and_do_upload(
  File "/home/airflow/.local/lib/python3.12/site-packages/google/cloud/storage/blob.py", line 2637, in _prep_and_do_upload
    created_json = self._do_upload(
                   ^^^^^^^^^^^^^^^^
  File "/home/airflow/.local/lib/python3.12/site-packages/google/cloud/storage/blob.py", line 2443, in _do_upload
    response = self._do_multipart_upload(
               ^^^^^^^^^^^^^^^^^^^^^^^^^^
  File "/home/airflow/.local/lib/python3.12/site-packages/google/cloud/storage/blob.py", line 1956, in _do_multipart_upload
    response = upload.transmit(
               ^^^^^^^^^^^^^^^^
  File "/home/airflow/.local/lib/python3.12/site-packages/google/resumable_media/requests/upload.py", line 153, in transmit
    return _request_helpers.wait_and_retry(
           ^^^^^^^^^^^^^^^^^^^^^^^^^^^^^^^^
  File "/home/airflow/.local/lib/python3.12/site-packages/google/resumable_media/requests/_request_helpers.py", line 178, in wait_and_retry
    raise error
  File "/home/airflow/.local/lib/python3.12/site-packages/google/resumable_media/requests/_request_helpers.py", line 155, in wait_and_retry
    response = func()
               ^^^^^^
  File "/home/airflow/.local/lib/python3.12/site-packages/google/resumable_media/requests/upload.py", line 145, in retriable_request
    result = transport.request(
             ^^^^^^^^^^^^^^^^^^
  File "/home/airflow/.local/lib/python3.12/site-packages/google/auth/transport/requests.py", line 541, in request
    response = super(AuthorizedSession, self).request(
               ^^^^^^^^^^^^^^^^^^^^^^^^^^^^^^^^^^^^^^^
  File "/home/airflow/.local/lib/python3.12/site-packages/requests/sessions.py", line 589, in request
    resp = self.send(prep, **send_kwargs)
           ^^^^^^^^^^^^^^^^^^^^^^^^^^^^^^
  File "/home/airflow/.local/lib/python3.12/site-packages/requests/sessions.py", line 703, in send
    r = adapter.send(request, **kwargs)
        ^^^^^^^^^^^^^^^^^^^^^^^^^^^^^^^
  File "/home/airflow/.local/lib/python3.12/site-packages/requests/adapters.py", line 532, in send
    raise ReadTimeout(e, request=request)
requests.exceptions.ReadTimeout: HTTPSConnectionPool(host='storage.googleapis.com', port=443): Read timed out. (read timeout=60)
[2024-06-23T15:01:15.698+0000] {taskinstance.py:1206} INFO - Marking task as UP_FOR_RETRY. dag_id=etl_all_dags_v1, task_id=load_firebase, run_id=scheduled__2024-06-21T00:00:00+00:00, execution_date=20240621T000000, start_date=20240623T145545, end_date=20240623T150115
[2024-06-23T15:01:16.131+0000] {standard_task_runner.py:110} ERROR - Failed to execute job 65 for task load_firebase (HTTPSConnectionPool(host='storage.googleapis.com', port=443): Read timed out. (read timeout=60); 150)
[2024-06-23T15:01:16.353+0000] {local_task_job_runner.py:240} INFO - Task exited with return code 1
[2024-06-23T15:01:16.476+0000] {taskinstance.py:3503} INFO - 0 downstream tasks scheduled from follow-on schedule check
[2024-06-23T15:01:16.491+0000] {local_task_job_runner.py:222} INFO - ::endgroup::
