[2024-06-26T14:04:40.741+0000] {local_task_job_runner.py:120} INFO - ::group::Pre task execution logs
[2024-06-26T14:04:40.775+0000] {taskinstance.py:2076} INFO - Dependencies all met for dep_context=non-requeueable deps ti=<TaskInstance: peduli_pintar_elt_all_dags_v1.extract_data scheduled__2024-06-23T00:00:00+00:00 [queued]>
[2024-06-26T14:04:40.786+0000] {taskinstance.py:2076} INFO - Dependencies all met for dep_context=requeueable deps ti=<TaskInstance: peduli_pintar_elt_all_dags_v1.extract_data scheduled__2024-06-23T00:00:00+00:00 [queued]>
[2024-06-26T14:04:40.789+0000] {taskinstance.py:2306} INFO - Starting attempt 2 of 5
[2024-06-26T14:04:40.826+0000] {taskinstance.py:2330} INFO - Executing <Task(ExtractData): extract_data> on 2024-06-23 00:00:00+00:00
[2024-06-26T14:04:40.838+0000] {warnings.py:112} WARNING - /home/***/.local/lib/python3.12/site-packages/***/task/task_runner/standard_task_runner.py:61: DeprecationWarning: This process (pid=98) is multi-threaded, use of fork() may lead to deadlocks in the child.
  pid = os.fork()

[2024-06-26T14:04:40.840+0000] {standard_task_runner.py:63} INFO - Started process 100 to run task
[2024-06-26T14:04:40.841+0000] {standard_task_runner.py:90} INFO - Running: ['***', 'tasks', 'run', 'peduli_pintar_elt_all_dags_v1', 'extract_data', 'scheduled__2024-06-23T00:00:00+00:00', '--job-id', '11', '--raw', '--subdir', 'DAGS_FOLDER/etl_all_dags.py', '--cfg-path', '/tmp/tmp22283w5q']
[2024-06-26T14:04:40.844+0000] {standard_task_runner.py:91} INFO - Job 11: Subtask extract_data
[2024-06-26T14:04:40.900+0000] {task_command.py:426} INFO - Running <TaskInstance: peduli_pintar_elt_all_dags_v1.extract_data scheduled__2024-06-23T00:00:00+00:00 [running]> on host 7ecff3f83b62
[2024-06-26T14:04:41.009+0000] {taskinstance.py:2648} INFO - Exporting env vars: AIRFLOW_CTX_DAG_OWNER='Kelompok 5 Capstone DE' AIRFLOW_CTX_DAG_ID='peduli_pintar_elt_all_dags_v1' AIRFLOW_CTX_TASK_ID='extract_data' AIRFLOW_CTX_EXECUTION_DATE='2024-06-23T00:00:00+00:00' AIRFLOW_CTX_TRY_NUMBER='2' AIRFLOW_CTX_DAG_RUN_ID='scheduled__2024-06-23T00:00:00+00:00'
[2024-06-26T14:04:41.011+0000] {taskinstance.py:430} INFO - ::endgroup::
[2024-06-26T14:04:41.058+0000] {base.py:84} INFO - Using connection ID 'EXTERNAL_DB_CONN_CAPSTONE_DE' for task execution.
[2024-06-26T14:04:41.402+0000] {sql.py:487} INFO - Running statement: SHOW TABLES, parameters: None
[2024-06-26T14:04:41.434+0000] {sql.py:496} INFO - Rows affected: 22
[2024-06-26T14:04:41.558+0000] {base.py:84} INFO - Using connection ID 'EXTERNAL_DB_CONN_CAPSTONE_DE' for task execution.
[2024-06-26T14:04:41.874+0000] {sql.py:487} INFO - Running statement: SHOW COLUMNS FROM admin_notifications, parameters: None
[2024-06-26T14:04:41.906+0000] {sql.py:496} INFO - Rows affected: 8
[2024-06-26T14:04:41.949+0000] {base.py:84} INFO - Using connection ID 'EXTERNAL_DB_CONN_CAPSTONE_DE' for task execution.
[2024-06-26T14:04:42.340+0000] {sql.py:487} INFO - Running statement: SELECT * FROM admin_notifications, parameters: None
[2024-06-26T14:04:42.407+0000] {sql.py:496} INFO - Rows affected: 82
[2024-06-26T14:04:42.493+0000] {base.py:84} INFO - Using connection ID 'EXTERNAL_DB_CONN_CAPSTONE_DE' for task execution.
[2024-06-26T14:04:42.807+0000] {sql.py:487} INFO - Running statement: SHOW COLUMNS FROM admins, parameters: None
[2024-06-26T14:04:42.840+0000] {sql.py:496} INFO - Rows affected: 8
[2024-06-26T14:04:42.878+0000] {base.py:84} INFO - Using connection ID 'EXTERNAL_DB_CONN_CAPSTONE_DE' for task execution.
[2024-06-26T14:04:43.235+0000] {sql.py:487} INFO - Running statement: SELECT * FROM admins, parameters: None
[2024-06-26T14:04:43.267+0000] {sql.py:496} INFO - Rows affected: 2
[2024-06-26T14:04:43.309+0000] {base.py:84} INFO - Using connection ID 'EXTERNAL_DB_CONN_CAPSTONE_DE' for task execution.
[2024-06-26T14:04:43.623+0000] {sql.py:487} INFO - Running statement: SHOW COLUMNS FROM applications, parameters: None
[2024-06-26T14:04:43.657+0000] {sql.py:496} INFO - Rows affected: 11
[2024-06-26T14:04:43.702+0000] {base.py:84} INFO - Using connection ID 'EXTERNAL_DB_CONN_CAPSTONE_DE' for task execution.
[2024-06-26T14:04:44.001+0000] {sql.py:487} INFO - Running statement: SELECT * FROM applications, parameters: None
[2024-06-26T14:04:44.070+0000] {sql.py:496} INFO - Rows affected: 133
[2024-06-26T14:04:44.111+0000] {base.py:84} INFO - Using connection ID 'EXTERNAL_DB_CONN_CAPSTONE_DE' for task execution.
[2024-06-26T14:04:45.465+0000] {sql.py:487} INFO - Running statement: SHOW COLUMNS FROM articles, parameters: None
[2024-06-26T14:04:45.505+0000] {sql.py:496} INFO - Rows affected: 8
[2024-06-26T14:04:45.540+0000] {base.py:84} INFO - Using connection ID 'EXTERNAL_DB_CONN_CAPSTONE_DE' for task execution.
[2024-06-26T14:04:45.863+0000] {sql.py:487} INFO - Running statement: SELECT * FROM articles, parameters: None
[2024-06-26T14:04:45.934+0000] {sql.py:496} INFO - Rows affected: 28
[2024-06-26T14:04:45.978+0000] {base.py:84} INFO - Using connection ID 'EXTERNAL_DB_CONN_CAPSTONE_DE' for task execution.
[2024-06-26T14:04:47.299+0000] {sql.py:487} INFO - Running statement: SHOW COLUMNS FROM comments, parameters: None
[2024-06-26T14:04:47.339+0000] {sql.py:496} INFO - Rows affected: 8
[2024-06-26T14:04:47.379+0000] {base.py:84} INFO - Using connection ID 'EXTERNAL_DB_CONN_CAPSTONE_DE' for task execution.
[2024-06-26T14:04:47.689+0000] {sql.py:487} INFO - Running statement: SELECT * FROM comments, parameters: None
[2024-06-26T14:04:47.724+0000] {sql.py:496} INFO - Rows affected: 55
[2024-06-26T14:04:47.774+0000] {base.py:84} INFO - Using connection ID 'EXTERNAL_DB_CONN_CAPSTONE_DE' for task execution.
[2024-06-26T14:04:48.097+0000] {sql.py:487} INFO - Running statement: SHOW COLUMNS FROM donation_comments, parameters: None
[2024-06-26T14:04:48.132+0000] {sql.py:496} INFO - Rows affected: 7
[2024-06-26T14:04:48.172+0000] {base.py:84} INFO - Using connection ID 'EXTERNAL_DB_CONN_CAPSTONE_DE' for task execution.
[2024-06-26T14:04:49.467+0000] {sql.py:487} INFO - Running statement: SELECT * FROM donation_comments, parameters: None
[2024-06-26T14:04:49.496+0000] {sql.py:496} INFO - Rows affected: 0
[2024-06-26T14:04:49.556+0000] {base.py:84} INFO - Using connection ID 'EXTERNAL_DB_CONN_CAPSTONE_DE' for task execution.
[2024-06-26T14:04:49.875+0000] {sql.py:487} INFO - Running statement: SHOW COLUMNS FROM donation_manual_comments, parameters: None
[2024-06-26T14:04:49.908+0000] {sql.py:496} INFO - Rows affected: 7
[2024-06-26T14:04:49.945+0000] {base.py:84} INFO - Using connection ID 'EXTERNAL_DB_CONN_CAPSTONE_DE' for task execution.
[2024-06-26T14:04:50.274+0000] {sql.py:487} INFO - Running statement: SELECT * FROM donation_manual_comments, parameters: None
[2024-06-26T14:04:50.307+0000] {sql.py:496} INFO - Rows affected: 90
[2024-06-26T14:04:50.352+0000] {base.py:84} INFO - Using connection ID 'EXTERNAL_DB_CONN_CAPSTONE_DE' for task execution.
[2024-06-26T14:04:50.769+0000] {sql.py:487} INFO - Running statement: SHOW COLUMNS FROM donation_manuals, parameters: None
[2024-06-26T14:04:50.804+0000] {sql.py:496} INFO - Rows affected: 9
[2024-06-26T14:04:50.848+0000] {base.py:84} INFO - Using connection ID 'EXTERNAL_DB_CONN_CAPSTONE_DE' for task execution.
[2024-06-26T14:04:52.136+0000] {sql.py:487} INFO - Running statement: SELECT * FROM donation_manuals, parameters: None
[2024-06-26T14:04:52.195+0000] {sql.py:496} INFO - Rows affected: 196
[2024-06-26T14:04:52.231+0000] {base.py:84} INFO - Using connection ID 'EXTERNAL_DB_CONN_CAPSTONE_DE' for task execution.
[2024-06-26T14:04:52.561+0000] {sql.py:487} INFO - Running statement: SHOW COLUMNS FROM donations, parameters: None
[2024-06-26T14:04:52.594+0000] {sql.py:496} INFO - Rows affected: 11
[2024-06-26T14:04:52.632+0000] {base.py:84} INFO - Using connection ID 'EXTERNAL_DB_CONN_CAPSTONE_DE' for task execution.
[2024-06-26T14:04:52.946+0000] {sql.py:487} INFO - Running statement: SELECT * FROM donations, parameters: None
[2024-06-26T14:04:52.979+0000] {sql.py:496} INFO - Rows affected: 10
[2024-06-26T14:04:53.019+0000] {base.py:84} INFO - Using connection ID 'EXTERNAL_DB_CONN_CAPSTONE_DE' for task execution.
[2024-06-26T14:04:53.343+0000] {sql.py:487} INFO - Running statement: SHOW COLUMNS FROM fundraising_categories, parameters: None
[2024-06-26T14:04:53.376+0000] {sql.py:496} INFO - Rows affected: 5
[2024-06-26T14:04:53.429+0000] {base.py:84} INFO - Using connection ID 'EXTERNAL_DB_CONN_CAPSTONE_DE' for task execution.
[2024-06-26T14:04:54.766+0000] {sql.py:487} INFO - Running statement: SELECT * FROM fundraising_categories, parameters: None
[2024-06-26T14:04:54.803+0000] {sql.py:496} INFO - Rows affected: 4
[2024-06-26T14:04:54.855+0000] {base.py:84} INFO - Using connection ID 'EXTERNAL_DB_CONN_CAPSTONE_DE' for task execution.
[2024-06-26T14:04:55.154+0000] {sql.py:487} INFO - Running statement: SHOW COLUMNS FROM fundraisings, parameters: None
[2024-06-26T14:04:55.187+0000] {sql.py:496} INFO - Rows affected: 14
[2024-06-26T14:04:55.455+0000] {base.py:84} INFO - Using connection ID 'EXTERNAL_DB_CONN_CAPSTONE_DE' for task execution.
[2024-06-26T14:05:02.285+0000] {sql.py:487} INFO - Running statement: SELECT * FROM fundraisings, parameters: None
[2024-06-26T14:05:02.362+0000] {sql.py:496} INFO - Rows affected: 35
[2024-06-26T14:05:13.737+0000] {connection.py:513} ERROR - Unable to retrieve connection from secrets backend (MetastoreBackend). Checking subsequent secrets backend.
Traceback (most recent call last):
  File "/home/airflow/.local/lib/python3.12/site-packages/sqlalchemy/engine/base.py", line 3371, in _wrap_pool_connect
    return fn()
           ^^^^
  File "/home/airflow/.local/lib/python3.12/site-packages/sqlalchemy/pool/base.py", line 327, in connect
    return _ConnectionFairy._checkout(self)
           ^^^^^^^^^^^^^^^^^^^^^^^^^^^^^^^^
  File "/home/airflow/.local/lib/python3.12/site-packages/sqlalchemy/pool/base.py", line 894, in _checkout
    fairy = _ConnectionRecord.checkout(pool)
            ^^^^^^^^^^^^^^^^^^^^^^^^^^^^^^^^
  File "/home/airflow/.local/lib/python3.12/site-packages/sqlalchemy/pool/base.py", line 493, in checkout
    rec = pool._do_get()
          ^^^^^^^^^^^^^^
  File "/home/airflow/.local/lib/python3.12/site-packages/sqlalchemy/pool/impl.py", line 256, in _do_get
    return self._create_connection()
           ^^^^^^^^^^^^^^^^^^^^^^^^^
  File "/home/airflow/.local/lib/python3.12/site-packages/sqlalchemy/pool/base.py", line 273, in _create_connection
    return _ConnectionRecord(self)
           ^^^^^^^^^^^^^^^^^^^^^^^
  File "/home/airflow/.local/lib/python3.12/site-packages/sqlalchemy/pool/base.py", line 388, in __init__
    self.__connect()
  File "/home/airflow/.local/lib/python3.12/site-packages/sqlalchemy/pool/base.py", line 690, in __connect
    with util.safe_reraise():
  File "/home/airflow/.local/lib/python3.12/site-packages/sqlalchemy/util/langhelpers.py", line 70, in __exit__
    compat.raise_(
  File "/home/airflow/.local/lib/python3.12/site-packages/sqlalchemy/util/compat.py", line 211, in raise_
    raise exception
  File "/home/airflow/.local/lib/python3.12/site-packages/sqlalchemy/pool/base.py", line 686, in __connect
    self.dbapi_connection = connection = pool._invoke_creator(self)
                                         ^^^^^^^^^^^^^^^^^^^^^^^^^^
  File "/home/airflow/.local/lib/python3.12/site-packages/sqlalchemy/engine/create.py", line 574, in connect
    return dialect.connect(*cargs, **cparams)
           ^^^^^^^^^^^^^^^^^^^^^^^^^^^^^^^^^^
  File "/home/airflow/.local/lib/python3.12/site-packages/sqlalchemy/engine/default.py", line 598, in connect
    return self.dbapi.connect(*cargs, **cparams)
           ^^^^^^^^^^^^^^^^^^^^^^^^^^^^^^^^^^^^^
  File "/home/airflow/.local/lib/python3.12/site-packages/psycopg2/__init__.py", line 122, in connect
    conn = _connect(dsn, connection_factory=connection_factory, **kwasync)
           ^^^^^^^^^^^^^^^^^^^^^^^^^^^^^^^^^^^^^^^^^^^^^^^^^^^^^^^^^^^^^^^
psycopg2.OperationalError: could not translate host name "postgres" to address: Temporary failure in name resolution


The above exception was the direct cause of the following exception:

Traceback (most recent call last):
  File "/home/airflow/.local/lib/python3.12/site-packages/airflow/models/connection.py", line 508, in get_connection_from_secrets
    conn = secrets_backend.get_connection(conn_id=conn_id)
           ^^^^^^^^^^^^^^^^^^^^^^^^^^^^^^^^^^^^^^^^^^^^^^^
  File "/home/airflow/.local/lib/python3.12/site-packages/airflow/utils/session.py", line 79, in wrapper
    return func(*args, session=session, **kwargs)
           ^^^^^^^^^^^^^^^^^^^^^^^^^^^^^^^^^^^^^^
  File "/home/airflow/.local/lib/python3.12/site-packages/airflow/secrets/metastore.py", line 43, in get_connection
    return MetastoreBackend._fetch_connection(conn_id, session=session)
           ^^^^^^^^^^^^^^^^^^^^^^^^^^^^^^^^^^^^^^^^^^^^^^^^^^^^^^^^^^^^
  File "/home/airflow/.local/lib/python3.12/site-packages/airflow/api_internal/internal_api_call.py", line 115, in wrapper
    return func(*args, **kwargs)
           ^^^^^^^^^^^^^^^^^^^^^
  File "/home/airflow/.local/lib/python3.12/site-packages/airflow/utils/session.py", line 76, in wrapper
    return func(*args, **kwargs)
           ^^^^^^^^^^^^^^^^^^^^^
  File "/home/airflow/.local/lib/python3.12/site-packages/airflow/secrets/metastore.py", line 74, in _fetch_connection
    conn = session.scalar(select(Connection).where(Connection.conn_id == conn_id).limit(1))
           ^^^^^^^^^^^^^^^^^^^^^^^^^^^^^^^^^^^^^^^^^^^^^^^^^^^^^^^^^^^^^^^^^^^^^^^^^^^^^^^^
  File "/home/airflow/.local/lib/python3.12/site-packages/sqlalchemy/orm/session.py", line 1747, in scalar
    return self.execute(
           ^^^^^^^^^^^^^
  File "/home/airflow/.local/lib/python3.12/site-packages/sqlalchemy/orm/session.py", line 1716, in execute
    conn = self._connection_for_bind(bind)
           ^^^^^^^^^^^^^^^^^^^^^^^^^^^^^^^
  File "/home/airflow/.local/lib/python3.12/site-packages/sqlalchemy/orm/session.py", line 1555, in _connection_for_bind
    return self._transaction._connection_for_bind(
           ^^^^^^^^^^^^^^^^^^^^^^^^^^^^^^^^^^^^^^^
  File "/home/airflow/.local/lib/python3.12/site-packages/sqlalchemy/orm/session.py", line 750, in _connection_for_bind
    conn = bind.connect()
           ^^^^^^^^^^^^^^
  File "/home/airflow/.local/lib/python3.12/site-packages/sqlalchemy/future/engine.py", line 412, in connect
    return super(Engine, self).connect()
           ^^^^^^^^^^^^^^^^^^^^^^^^^^^^^
  File "/home/airflow/.local/lib/python3.12/site-packages/sqlalchemy/engine/base.py", line 3325, in connect
    return self._connection_cls(self, close_with_result=close_with_result)
           ^^^^^^^^^^^^^^^^^^^^^^^^^^^^^^^^^^^^^^^^^^^^^^^^^^^^^^^^^^^^^^^
  File "/home/airflow/.local/lib/python3.12/site-packages/sqlalchemy/engine/base.py", line 96, in __init__
    else engine.raw_connection()
         ^^^^^^^^^^^^^^^^^^^^^^^
  File "/home/airflow/.local/lib/python3.12/site-packages/sqlalchemy/engine/base.py", line 3404, in raw_connection
    return self._wrap_pool_connect(self.pool.connect, _connection)
           ^^^^^^^^^^^^^^^^^^^^^^^^^^^^^^^^^^^^^^^^^^^^^^^^^^^^^^^
  File "/home/airflow/.local/lib/python3.12/site-packages/sqlalchemy/engine/base.py", line 3374, in _wrap_pool_connect
    Connection._handle_dbapi_exception_noconnection(
  File "/home/airflow/.local/lib/python3.12/site-packages/sqlalchemy/engine/base.py", line 2208, in _handle_dbapi_exception_noconnection
    util.raise_(
  File "/home/airflow/.local/lib/python3.12/site-packages/sqlalchemy/util/compat.py", line 211, in raise_
    raise exception
  File "/home/airflow/.local/lib/python3.12/site-packages/sqlalchemy/engine/base.py", line 3371, in _wrap_pool_connect
    return fn()
           ^^^^
  File "/home/airflow/.local/lib/python3.12/site-packages/sqlalchemy/pool/base.py", line 327, in connect
    return _ConnectionFairy._checkout(self)
           ^^^^^^^^^^^^^^^^^^^^^^^^^^^^^^^^
  File "/home/airflow/.local/lib/python3.12/site-packages/sqlalchemy/pool/base.py", line 894, in _checkout
    fairy = _ConnectionRecord.checkout(pool)
            ^^^^^^^^^^^^^^^^^^^^^^^^^^^^^^^^
  File "/home/airflow/.local/lib/python3.12/site-packages/sqlalchemy/pool/base.py", line 493, in checkout
    rec = pool._do_get()
          ^^^^^^^^^^^^^^
  File "/home/airflow/.local/lib/python3.12/site-packages/sqlalchemy/pool/impl.py", line 256, in _do_get
    return self._create_connection()
           ^^^^^^^^^^^^^^^^^^^^^^^^^
  File "/home/airflow/.local/lib/python3.12/site-packages/sqlalchemy/pool/base.py", line 273, in _create_connection
    return _ConnectionRecord(self)
           ^^^^^^^^^^^^^^^^^^^^^^^
  File "/home/airflow/.local/lib/python3.12/site-packages/sqlalchemy/pool/base.py", line 388, in __init__
    self.__connect()
  File "/home/airflow/.local/lib/python3.12/site-packages/sqlalchemy/pool/base.py", line 690, in __connect
    with util.safe_reraise():
  File "/home/airflow/.local/lib/python3.12/site-packages/sqlalchemy/util/langhelpers.py", line 70, in __exit__
    compat.raise_(
  File "/home/airflow/.local/lib/python3.12/site-packages/sqlalchemy/util/compat.py", line 211, in raise_
    raise exception
  File "/home/airflow/.local/lib/python3.12/site-packages/sqlalchemy/pool/base.py", line 686, in __connect
    self.dbapi_connection = connection = pool._invoke_creator(self)
                                         ^^^^^^^^^^^^^^^^^^^^^^^^^^
  File "/home/airflow/.local/lib/python3.12/site-packages/sqlalchemy/engine/create.py", line 574, in connect
    return dialect.connect(*cargs, **cparams)
           ^^^^^^^^^^^^^^^^^^^^^^^^^^^^^^^^^^
  File "/home/airflow/.local/lib/python3.12/site-packages/sqlalchemy/engine/default.py", line 598, in connect
    return self.dbapi.connect(*cargs, **cparams)
           ^^^^^^^^^^^^^^^^^^^^^^^^^^^^^^^^^^^^^
  File "/home/airflow/.local/lib/python3.12/site-packages/psycopg2/__init__.py", line 122, in connect
    conn = _connect(dsn, connection_factory=connection_factory, **kwasync)
           ^^^^^^^^^^^^^^^^^^^^^^^^^^^^^^^^^^^^^^^^^^^^^^^^^^^^^^^^^^^^^^^
sqlalchemy.exc.OperationalError: (psycopg2.OperationalError) could not translate host name "postgres" to address: Temporary failure in name resolution

(Background on this error at: https://sqlalche.me/e/14/e3q8)
[2024-06-26T14:05:18.500+0000] {taskinstance.py:441} INFO - ::group::Post task execution logs
[2024-06-26T14:05:19.617+0000] {taskinstance.py:2905} ERROR - Task failed with exception
Traceback (most recent call last):
  File "/home/airflow/.local/lib/python3.12/site-packages/airflow/models/taskinstance.py", line 465, in _execute_task
    result = _execute_callable(context=context, **execute_callable_kwargs)
             ^^^^^^^^^^^^^^^^^^^^^^^^^^^^^^^^^^^^^^^^^^^^^^^^^^^^^^^^^^^^^
  File "/home/airflow/.local/lib/python3.12/site-packages/airflow/models/taskinstance.py", line 432, in _execute_callable
    return execute_callable(context=context, **execute_callable_kwargs)
           ^^^^^^^^^^^^^^^^^^^^^^^^^^^^^^^^^^^^^^^^^^^^^^^^^^^^^^^^^^^^
  File "/home/airflow/.local/lib/python3.12/site-packages/airflow/models/baseoperator.py", line 401, in wrapper
    return func(self, *args, **kwargs)
           ^^^^^^^^^^^^^^^^^^^^^^^^^^^
  File "/opt/airflow/dags/custom_operator/etl_all_operator.py", line 53, in execute
    dataframes, table_names = self.extract_data_from_external_db(text_columns)
                              ^^^^^^^^^^^^^^^^^^^^^^^^^^^^^^^^^^^^^^^^^^^^^^^^
  File "/opt/airflow/dags/custom_operator/etl_all_operator.py", line 32, in extract_data_from_external_db
    column_names = [col[0] for col in mysql_hook.get_records(f"SHOW COLUMNS FROM {table}")]
                                      ^^^^^^^^^^^^^^^^^^^^^^^^^^^^^^^^^^^^^^^^^^^^^^^^^^^^
  File "/home/airflow/.local/lib/python3.12/site-packages/airflow/providers/common/sql/hooks/sql.py", line 303, in get_records
    return self.run(sql=sql, parameters=parameters, handler=fetch_all_handler)
           ^^^^^^^^^^^^^^^^^^^^^^^^^^^^^^^^^^^^^^^^^^^^^^^^^^^^^^^^^^^^^^^^^^^
  File "/home/airflow/.local/lib/python3.12/site-packages/airflow/providers/common/sql/hooks/sql.py", line 431, in run
    with self._create_autocommit_connection(autocommit) as conn:
  File "/usr/local/lib/python3.12/contextlib.py", line 137, in __enter__
    return next(self.gen)
           ^^^^^^^^^^^^^^
  File "/home/airflow/.local/lib/python3.12/site-packages/airflow/providers/common/sql/hooks/sql.py", line 551, in _create_autocommit_connection
    with closing(self.get_conn()) as conn:
                 ^^^^^^^^^^^^^^^
  File "/home/airflow/.local/lib/python3.12/site-packages/airflow/providers/mysql/hooks/mysql.py", line 188, in get_conn
    conn = self.connection or self.get_connection(getattr(self, self.conn_name_attr))
                              ^^^^^^^^^^^^^^^^^^^^^^^^^^^^^^^^^^^^^^^^^^^^^^^^^^^^^^^
  File "/home/airflow/.local/lib/python3.12/site-packages/airflow/hooks/base.py", line 83, in get_connection
    conn = Connection.get_connection_from_secrets(conn_id)
           ^^^^^^^^^^^^^^^^^^^^^^^^^^^^^^^^^^^^^^^^^^^^^^^
  File "/home/airflow/.local/lib/python3.12/site-packages/airflow/models/connection.py", line 519, in get_connection_from_secrets
    raise AirflowNotFoundException(f"The conn_id `{conn_id}` isn't defined")
airflow.exceptions.AirflowNotFoundException: The conn_id `EXTERNAL_DB_CONN_CAPSTONE_DE` isn't defined
[2024-06-26T14:05:19.814+0000] {taskinstance.py:1206} INFO - Marking task as UP_FOR_RETRY. dag_id=peduli_pintar_elt_all_dags_v1, task_id=extract_data, run_id=scheduled__2024-06-23T00:00:00+00:00, execution_date=20240623T000000, start_date=20240626T140440, end_date=20240626T140519
[2024-06-26T14:05:19.942+0000] {standard_task_runner.py:110} ERROR - Failed to execute job 11 for task extract_data (The conn_id `EXTERNAL_DB_CONN_CAPSTONE_DE` isn't defined; 100)
[2024-06-26T14:05:20.247+0000] {local_task_job_runner.py:240} INFO - Task exited with return code 1
[2024-06-26T14:05:20.337+0000] {taskinstance.py:3503} INFO - 0 downstream tasks scheduled from follow-on schedule check
[2024-06-26T14:05:20.347+0000] {local_task_job_runner.py:222} INFO - ::endgroup::
