[2024-06-27T03:32:30.398+0000] {local_task_job_runner.py:120} INFO - ::group::Pre task execution logs
[2024-06-27T03:32:30.495+0000] {taskinstance.py:2076} INFO - Dependencies all met for dep_context=non-requeueable deps ti=<TaskInstance: coba_ds_v3.load_gbq scheduled__2024-06-24T00:00:00+00:00 [queued]>
[2024-06-27T03:32:30.522+0000] {taskinstance.py:2076} INFO - Dependencies all met for dep_context=requeueable deps ti=<TaskInstance: coba_ds_v3.load_gbq scheduled__2024-06-24T00:00:00+00:00 [queued]>
[2024-06-27T03:32:30.523+0000] {taskinstance.py:2306} INFO - Starting attempt 4 of 4
[2024-06-27T03:32:30.570+0000] {taskinstance.py:2330} INFO - Executing <Task(LoadGoogleBigQuery): load_gbq> on 2024-06-24 00:00:00+00:00
[2024-06-27T03:32:30.620+0000] {warnings.py:112} WARNING - /home/***/.local/lib/python3.12/site-packages/***/task/task_runner/standard_task_runner.py:61: DeprecationWarning: This process (pid=56) is multi-threaded, use of fork() may lead to deadlocks in the child.
  pid = os.fork()

[2024-06-27T03:32:30.626+0000] {standard_task_runner.py:63} INFO - Started process 61 to run task
[2024-06-27T03:32:30.629+0000] {standard_task_runner.py:90} INFO - Running: ['***', 'tasks', 'run', 'coba_ds_v3', 'load_gbq', 'scheduled__2024-06-24T00:00:00+00:00', '--job-id', '153', '--raw', '--subdir', 'DAGS_FOLDER/etl_dags.py', '--cfg-path', '/tmp/tmpxmqhu95r']
[2024-06-27T03:32:30.636+0000] {standard_task_runner.py:91} INFO - Job 153: Subtask load_gbq
[2024-06-27T03:32:30.891+0000] {task_command.py:426} INFO - Running <TaskInstance: coba_ds_v3.load_gbq scheduled__2024-06-24T00:00:00+00:00 [running]> on host 0bef536324ed
[2024-06-27T03:32:31.413+0000] {taskinstance.py:2648} INFO - Exporting env vars: AIRFLOW_CTX_DAG_OWNER='Kelompok 5 Capstone DE' AIRFLOW_CTX_DAG_ID='coba_ds_v3' AIRFLOW_CTX_TASK_ID='load_gbq' AIRFLOW_CTX_EXECUTION_DATE='2024-06-24T00:00:00+00:00' AIRFLOW_CTX_TRY_NUMBER='4' AIRFLOW_CTX_DAG_RUN_ID='scheduled__2024-06-24T00:00:00+00:00'
[2024-06-27T03:32:31.418+0000] {taskinstance.py:430} INFO - ::endgroup::
[2024-06-27T03:32:31.571+0000] {connection.py:274} WARNING - Connection schemes (type: google_cloud_platform) shall not contain '_' according to RFC3986.
[2024-06-27T03:32:31.590+0000] {base.py:84} INFO - Using connection ID 'gcp_conn_capstone_de' for task execution.
[2024-06-27T03:32:31.881+0000] {logging_mixin.py:188} INFO - File 20240623_fact_donation_transaction.csv does not match partition date 20240624, skipping.
[2024-06-27T03:32:33.500+0000] {taskinstance.py:441} INFO - ::group::Post task execution logs
[2024-06-27T03:32:33.502+0000] {taskinstance.py:2905} ERROR - Task failed with exception
Traceback (most recent call last):
  File "/home/airflow/.local/lib/python3.12/site-packages/google/cloud/bigquery/client.py", line 2584, in load_table_from_file
    response = self._do_multipart_upload(
               ^^^^^^^^^^^^^^^^^^^^^^^^^^
  File "/home/airflow/.local/lib/python3.12/site-packages/google/cloud/bigquery/client.py", line 3148, in _do_multipart_upload
    response = upload.transmit(
               ^^^^^^^^^^^^^^^^
  File "/home/airflow/.local/lib/python3.12/site-packages/google/resumable_media/requests/upload.py", line 153, in transmit
    return _request_helpers.wait_and_retry(
           ^^^^^^^^^^^^^^^^^^^^^^^^^^^^^^^^
  File "/home/airflow/.local/lib/python3.12/site-packages/google/resumable_media/requests/_request_helpers.py", line 155, in wait_and_retry
    response = func()
               ^^^^^^
  File "/home/airflow/.local/lib/python3.12/site-packages/google/resumable_media/requests/upload.py", line 149, in retriable_request
    self._process_response(result)
  File "/home/airflow/.local/lib/python3.12/site-packages/google/resumable_media/_upload.py", line 125, in _process_response
    _helpers.require_status_code(response, (http.client.OK,), self._get_status_code)
  File "/home/airflow/.local/lib/python3.12/site-packages/google/resumable_media/_helpers.py", line 108, in require_status_code
    raise common.InvalidResponse(
google.resumable_media.common.InvalidResponse: ('Request failed with status code', 400, 'Expected one of', 200)

During handling of the above exception, another exception occurred:

Traceback (most recent call last):
  File "/home/airflow/.local/lib/python3.12/site-packages/airflow/models/taskinstance.py", line 465, in _execute_task
    result = _execute_callable(context=context, **execute_callable_kwargs)
             ^^^^^^^^^^^^^^^^^^^^^^^^^^^^^^^^^^^^^^^^^^^^^^^^^^^^^^^^^^^^^
  File "/home/airflow/.local/lib/python3.12/site-packages/airflow/models/taskinstance.py", line 432, in _execute_callable
    return execute_callable(context=context, **execute_callable_kwargs)
           ^^^^^^^^^^^^^^^^^^^^^^^^^^^^^^^^^^^^^^^^^^^^^^^^^^^^^^^^^^^^
  File "/home/airflow/.local/lib/python3.12/site-packages/airflow/models/baseoperator.py", line 401, in wrapper
    return func(self, *args, **kwargs)
           ^^^^^^^^^^^^^^^^^^^^^^^^^^^
  File "/opt/airflow/dags/custom_operator/etl_operator.py", line 616, in execute
    self.upload_df_to_gbq(dataset_id_fact_ds, table_fact_table, ds, "dags/data_loaded/fact")
  File "/opt/airflow/dags/custom_operator/etl_operator.py", line 588, in upload_df_to_gbq
    load_job = client.load_table_from_dataframe(
               ^^^^^^^^^^^^^^^^^^^^^^^^^^^^^^^^^
  File "/home/airflow/.local/lib/python3.12/site-packages/google/cloud/bigquery/client.py", line 2824, in load_table_from_dataframe
    return self.load_table_from_file(
           ^^^^^^^^^^^^^^^^^^^^^^^^^^
  File "/home/airflow/.local/lib/python3.12/site-packages/google/cloud/bigquery/client.py", line 2588, in load_table_from_file
    raise exceptions.from_http_response(exc.response)
google.api_core.exceptions.BadRequest: 400 POST https://bigquery.googleapis.com/upload/bigquery/v2/projects/capstone-de2/jobs?uploadType=multipart: Provided Schema does not match Table capstone-de2:airflow_peduli_pintar_fact.fact_donation_transaction$20240624. Field goal_amount has changed type from INTEGER to FLOAT
[2024-06-27T03:32:33.548+0000] {taskinstance.py:1206} INFO - Marking task as FAILED. dag_id=coba_ds_v3, task_id=load_gbq, run_id=scheduled__2024-06-24T00:00:00+00:00, execution_date=20240624T000000, start_date=20240627T033230, end_date=20240627T033233
[2024-06-27T03:32:33.585+0000] {standard_task_runner.py:110} ERROR - Failed to execute job 153 for task load_gbq (400 POST https://bigquery.googleapis.com/upload/bigquery/v2/projects/capstone-de2/jobs?uploadType=multipart: Provided Schema does not match Table capstone-de2:airflow_peduli_pintar_fact.fact_donation_transaction$20240624. Field goal_amount has changed type from INTEGER to FLOAT; 61)
[2024-06-27T03:32:33.644+0000] {local_task_job_runner.py:240} INFO - Task exited with return code 1
[2024-06-27T03:32:33.687+0000] {taskinstance.py:3503} INFO - 0 downstream tasks scheduled from follow-on schedule check
[2024-06-27T03:32:33.691+0000] {local_task_job_runner.py:222} INFO - ::endgroup::
