[2024-06-27T03:37:06.539+0000] {local_task_job_runner.py:120} INFO - ::group::Pre task execution logs
[2024-06-27T03:37:06.640+0000] {taskinstance.py:2076} INFO - Dependencies all met for dep_context=non-requeueable deps ti=<TaskInstance: coba_ds_v4.load_gbq scheduled__2024-06-23T00:00:00+00:00 [queued]>
[2024-06-27T03:37:06.660+0000] {taskinstance.py:2076} INFO - Dependencies all met for dep_context=requeueable deps ti=<TaskInstance: coba_ds_v4.load_gbq scheduled__2024-06-23T00:00:00+00:00 [queued]>
[2024-06-27T03:37:06.661+0000] {taskinstance.py:2306} INFO - Starting attempt 1 of 4
[2024-06-27T03:37:06.699+0000] {taskinstance.py:2330} INFO - Executing <Task(LoadGoogleBigQuery): load_gbq> on 2024-06-23 00:00:00+00:00
[2024-06-27T03:37:06.749+0000] {warnings.py:112} WARNING - /home/***/.local/lib/python3.12/site-packages/***/task/task_runner/standard_task_runner.py:61: DeprecationWarning: This process (pid=120) is multi-threaded, use of fork() may lead to deadlocks in the child.
  pid = os.fork()

[2024-06-27T03:37:06.763+0000] {standard_task_runner.py:63} INFO - Started process 127 to run task
[2024-06-27T03:37:06.757+0000] {standard_task_runner.py:90} INFO - Running: ['***', 'tasks', 'run', 'coba_ds_v4', 'load_gbq', 'scheduled__2024-06-23T00:00:00+00:00', '--job-id', '155', '--raw', '--subdir', 'DAGS_FOLDER/etl_dags.py', '--cfg-path', '/tmp/tmphn8gy9ly']
[2024-06-27T03:37:06.772+0000] {standard_task_runner.py:91} INFO - Job 155: Subtask load_gbq
[2024-06-27T03:37:08.272+0000] {task_command.py:426} INFO - Running <TaskInstance: coba_ds_v4.load_gbq scheduled__2024-06-23T00:00:00+00:00 [running]> on host 0bef536324ed
[2024-06-27T03:37:09.460+0000] {taskinstance.py:2648} INFO - Exporting env vars: AIRFLOW_CTX_DAG_OWNER='Kelompok 5 Capstone DE' AIRFLOW_CTX_DAG_ID='coba_ds_v4' AIRFLOW_CTX_TASK_ID='load_gbq' AIRFLOW_CTX_EXECUTION_DATE='2024-06-23T00:00:00+00:00' AIRFLOW_CTX_TRY_NUMBER='1' AIRFLOW_CTX_DAG_RUN_ID='scheduled__2024-06-23T00:00:00+00:00'
[2024-06-27T03:37:09.475+0000] {taskinstance.py:430} INFO - ::endgroup::
[2024-06-27T03:37:09.639+0000] {connection.py:274} WARNING - Connection schemes (type: google_cloud_platform) shall not contain '_' according to RFC3986.
[2024-06-27T03:37:09.652+0000] {base.py:84} INFO - Using connection ID 'gcp_conn_capstone_de' for task execution.
[2024-06-27T03:37:22.023+0000] {connectionpool.py:874} WARNING - Retrying (Retry(total=2, connect=None, read=None, redirect=None, status=None)) after connection broken by 'NameResolutionError("<urllib3.connection.HTTPSConnection object at 0x7fcf26f44440>: Failed to resolve 'oauth2.googleapis.com' ([Errno -3] Temporary failure in name resolution)")': /token
[2024-06-27T03:37:40.612+0000] {connectionpool.py:874} WARNING - Retrying (Retry(total=1, connect=None, read=None, redirect=None, status=None)) after connection broken by 'NameResolutionError("<urllib3.connection.HTTPSConnection object at 0x7fcf26f44830>: Failed to resolve 'oauth2.googleapis.com' ([Errno -3] Temporary failure in name resolution)")': /token
[2024-06-27T03:37:48.745+0000] {logging_mixin.py:188} INFO - Loaded 1 rows into capstone-de2.***_peduli_pintar_fact.fact_donation_transaction$20240623
[2024-06-27T03:37:48.765+0000] {logging_mixin.py:188} INFO - File 20240624_fact_donation_transaction.csv does not match partition date 20240623, skipping.
[2024-06-27T03:37:48.771+0000] {logging_mixin.py:188} INFO - File 20240625_fact_donation_transaction.csv does not match partition date 20240623, skipping.
[2024-06-27T03:39:21.427+0000] {job.py:218} ERROR - Job heartbeat got an exception
Traceback (most recent call last):
  File "/home/airflow/.local/lib/python3.12/site-packages/sqlalchemy/engine/base.py", line 3371, in _wrap_pool_connect
    return fn()
           ^^^^
  File "/home/airflow/.local/lib/python3.12/site-packages/sqlalchemy/pool/base.py", line 327, in connect
    return _ConnectionFairy._checkout(self)
           ^^^^^^^^^^^^^^^^^^^^^^^^^^^^^^^^
  File "/home/airflow/.local/lib/python3.12/site-packages/sqlalchemy/pool/base.py", line 894, in _checkout
    fairy = _ConnectionRecord.checkout(pool)
            ^^^^^^^^^^^^^^^^^^^^^^^^^^^^^^^^
  File "/home/airflow/.local/lib/python3.12/site-packages/sqlalchemy/pool/base.py", line 493, in checkout
    rec = pool._do_get()
          ^^^^^^^^^^^^^^
  File "/home/airflow/.local/lib/python3.12/site-packages/sqlalchemy/pool/impl.py", line 256, in _do_get
    return self._create_connection()
           ^^^^^^^^^^^^^^^^^^^^^^^^^
  File "/home/airflow/.local/lib/python3.12/site-packages/sqlalchemy/pool/base.py", line 273, in _create_connection
    return _ConnectionRecord(self)
           ^^^^^^^^^^^^^^^^^^^^^^^
  File "/home/airflow/.local/lib/python3.12/site-packages/sqlalchemy/pool/base.py", line 388, in __init__
    self.__connect()
  File "/home/airflow/.local/lib/python3.12/site-packages/sqlalchemy/pool/base.py", line 690, in __connect
    with util.safe_reraise():
  File "/home/airflow/.local/lib/python3.12/site-packages/sqlalchemy/util/langhelpers.py", line 70, in __exit__
    compat.raise_(
  File "/home/airflow/.local/lib/python3.12/site-packages/sqlalchemy/util/compat.py", line 211, in raise_
    raise exception
  File "/home/airflow/.local/lib/python3.12/site-packages/sqlalchemy/pool/base.py", line 686, in __connect
    self.dbapi_connection = connection = pool._invoke_creator(self)
                                         ^^^^^^^^^^^^^^^^^^^^^^^^^^
  File "/home/airflow/.local/lib/python3.12/site-packages/sqlalchemy/engine/create.py", line 574, in connect
    return dialect.connect(*cargs, **cparams)
           ^^^^^^^^^^^^^^^^^^^^^^^^^^^^^^^^^^
  File "/home/airflow/.local/lib/python3.12/site-packages/sqlalchemy/engine/default.py", line 598, in connect
    return self.dbapi.connect(*cargs, **cparams)
           ^^^^^^^^^^^^^^^^^^^^^^^^^^^^^^^^^^^^^
  File "/home/airflow/.local/lib/python3.12/site-packages/psycopg2/__init__.py", line 122, in connect
    conn = _connect(dsn, connection_factory=connection_factory, **kwasync)
           ^^^^^^^^^^^^^^^^^^^^^^^^^^^^^^^^^^^^^^^^^^^^^^^^^^^^^^^^^^^^^^^
psycopg2.OperationalError: could not translate host name "postgres" to address: Temporary failure in name resolution


The above exception was the direct cause of the following exception:

Traceback (most recent call last):
  File "/home/airflow/.local/lib/python3.12/site-packages/airflow/jobs/job.py", line 192, in heartbeat
    self._merge_from(Job._fetch_from_db(self, session))
                     ^^^^^^^^^^^^^^^^^^^^^^^^^^^^^^^^^
  File "/home/airflow/.local/lib/python3.12/site-packages/airflow/api_internal/internal_api_call.py", line 115, in wrapper
    return func(*args, **kwargs)
           ^^^^^^^^^^^^^^^^^^^^^
  File "/home/airflow/.local/lib/python3.12/site-packages/airflow/utils/session.py", line 76, in wrapper
    return func(*args, **kwargs)
           ^^^^^^^^^^^^^^^^^^^^^
  File "/home/airflow/.local/lib/python3.12/site-packages/airflow/utils/retries.py", line 89, in wrapped_function
    for attempt in run_with_db_retries(max_retries=retries, logger=logger, **retry_kwargs):
  File "/home/airflow/.local/lib/python3.12/site-packages/tenacity/__init__.py", line 435, in __iter__
    do = self.iter(retry_state=retry_state)
         ^^^^^^^^^^^^^^^^^^^^^^^^^^^^^^^^^^
  File "/home/airflow/.local/lib/python3.12/site-packages/tenacity/__init__.py", line 368, in iter
    result = action(retry_state)
             ^^^^^^^^^^^^^^^^^^^
  File "/home/airflow/.local/lib/python3.12/site-packages/tenacity/__init__.py", line 410, in exc_check
    raise retry_exc.reraise()
          ^^^^^^^^^^^^^^^^^^^
  File "/home/airflow/.local/lib/python3.12/site-packages/tenacity/__init__.py", line 183, in reraise
    raise self.last_attempt.result()
          ^^^^^^^^^^^^^^^^^^^^^^^^^^
  File "/usr/local/lib/python3.12/concurrent/futures/_base.py", line 449, in result
    return self.__get_result()
           ^^^^^^^^^^^^^^^^^^^
  File "/usr/local/lib/python3.12/concurrent/futures/_base.py", line 401, in __get_result
    raise self._exception
  File "/home/airflow/.local/lib/python3.12/site-packages/airflow/utils/retries.py", line 98, in wrapped_function
    return func(*args, **kwargs)
           ^^^^^^^^^^^^^^^^^^^^^
  File "/home/airflow/.local/lib/python3.12/site-packages/airflow/jobs/job.py", line 316, in _fetch_from_db
    session.merge(job)
  File "/home/airflow/.local/lib/python3.12/site-packages/sqlalchemy/orm/session.py", line 3056, in merge
    return self._merge(
           ^^^^^^^^^^^^
  File "/home/airflow/.local/lib/python3.12/site-packages/sqlalchemy/orm/session.py", line 3136, in _merge
    merged = self.get(
             ^^^^^^^^^
  File "/home/airflow/.local/lib/python3.12/site-packages/sqlalchemy/orm/session.py", line 2853, in get
    return self._get_impl(
           ^^^^^^^^^^^^^^^
  File "/home/airflow/.local/lib/python3.12/site-packages/sqlalchemy/orm/session.py", line 2975, in _get_impl
    return db_load_fn(
           ^^^^^^^^^^^
  File "/home/airflow/.local/lib/python3.12/site-packages/sqlalchemy/orm/loading.py", line 530, in load_on_pk_identity
    session.execute(
  File "/home/airflow/.local/lib/python3.12/site-packages/sqlalchemy/orm/session.py", line 1716, in execute
    conn = self._connection_for_bind(bind)
           ^^^^^^^^^^^^^^^^^^^^^^^^^^^^^^^
  File "/home/airflow/.local/lib/python3.12/site-packages/sqlalchemy/orm/session.py", line 1555, in _connection_for_bind
    return self._transaction._connection_for_bind(
           ^^^^^^^^^^^^^^^^^^^^^^^^^^^^^^^^^^^^^^^
  File "/home/airflow/.local/lib/python3.12/site-packages/sqlalchemy/orm/session.py", line 750, in _connection_for_bind
    conn = bind.connect()
           ^^^^^^^^^^^^^^
  File "/home/airflow/.local/lib/python3.12/site-packages/sqlalchemy/future/engine.py", line 412, in connect
    return super(Engine, self).connect()
           ^^^^^^^^^^^^^^^^^^^^^^^^^^^^^
  File "/home/airflow/.local/lib/python3.12/site-packages/sqlalchemy/engine/base.py", line 3325, in connect
    return self._connection_cls(self, close_with_result=close_with_result)
           ^^^^^^^^^^^^^^^^^^^^^^^^^^^^^^^^^^^^^^^^^^^^^^^^^^^^^^^^^^^^^^^
  File "/home/airflow/.local/lib/python3.12/site-packages/sqlalchemy/engine/base.py", line 96, in __init__
    else engine.raw_connection()
         ^^^^^^^^^^^^^^^^^^^^^^^
  File "/home/airflow/.local/lib/python3.12/site-packages/sqlalchemy/engine/base.py", line 3404, in raw_connection
    return self._wrap_pool_connect(self.pool.connect, _connection)
           ^^^^^^^^^^^^^^^^^^^^^^^^^^^^^^^^^^^^^^^^^^^^^^^^^^^^^^^
  File "/home/airflow/.local/lib/python3.12/site-packages/sqlalchemy/engine/base.py", line 3374, in _wrap_pool_connect
    Connection._handle_dbapi_exception_noconnection(
  File "/home/airflow/.local/lib/python3.12/site-packages/sqlalchemy/engine/base.py", line 2208, in _handle_dbapi_exception_noconnection
    util.raise_(
  File "/home/airflow/.local/lib/python3.12/site-packages/sqlalchemy/util/compat.py", line 211, in raise_
    raise exception
  File "/home/airflow/.local/lib/python3.12/site-packages/sqlalchemy/engine/base.py", line 3371, in _wrap_pool_connect
    return fn()
           ^^^^
  File "/home/airflow/.local/lib/python3.12/site-packages/sqlalchemy/pool/base.py", line 327, in connect
    return _ConnectionFairy._checkout(self)
           ^^^^^^^^^^^^^^^^^^^^^^^^^^^^^^^^
  File "/home/airflow/.local/lib/python3.12/site-packages/sqlalchemy/pool/base.py", line 894, in _checkout
    fairy = _ConnectionRecord.checkout(pool)
            ^^^^^^^^^^^^^^^^^^^^^^^^^^^^^^^^
  File "/home/airflow/.local/lib/python3.12/site-packages/sqlalchemy/pool/base.py", line 493, in checkout
    rec = pool._do_get()
          ^^^^^^^^^^^^^^
  File "/home/airflow/.local/lib/python3.12/site-packages/sqlalchemy/pool/impl.py", line 256, in _do_get
    return self._create_connection()
           ^^^^^^^^^^^^^^^^^^^^^^^^^
  File "/home/airflow/.local/lib/python3.12/site-packages/sqlalchemy/pool/base.py", line 273, in _create_connection
    return _ConnectionRecord(self)
           ^^^^^^^^^^^^^^^^^^^^^^^
  File "/home/airflow/.local/lib/python3.12/site-packages/sqlalchemy/pool/base.py", line 388, in __init__
    self.__connect()
  File "/home/airflow/.local/lib/python3.12/site-packages/sqlalchemy/pool/base.py", line 690, in __connect
    with util.safe_reraise():
  File "/home/airflow/.local/lib/python3.12/site-packages/sqlalchemy/util/langhelpers.py", line 70, in __exit__
    compat.raise_(
  File "/home/airflow/.local/lib/python3.12/site-packages/sqlalchemy/util/compat.py", line 211, in raise_
    raise exception
  File "/home/airflow/.local/lib/python3.12/site-packages/sqlalchemy/pool/base.py", line 686, in __connect
    self.dbapi_connection = connection = pool._invoke_creator(self)
                                         ^^^^^^^^^^^^^^^^^^^^^^^^^^
  File "/home/airflow/.local/lib/python3.12/site-packages/sqlalchemy/engine/create.py", line 574, in connect
    return dialect.connect(*cargs, **cparams)
           ^^^^^^^^^^^^^^^^^^^^^^^^^^^^^^^^^^
  File "/home/airflow/.local/lib/python3.12/site-packages/sqlalchemy/engine/default.py", line 598, in connect
    return self.dbapi.connect(*cargs, **cparams)
           ^^^^^^^^^^^^^^^^^^^^^^^^^^^^^^^^^^^^^
  File "/home/airflow/.local/lib/python3.12/site-packages/psycopg2/__init__.py", line 122, in connect
    conn = _connect(dsn, connection_factory=connection_factory, **kwasync)
           ^^^^^^^^^^^^^^^^^^^^^^^^^^^^^^^^^^^^^^^^^^^^^^^^^^^^^^^^^^^^^^^
sqlalchemy.exc.OperationalError: (psycopg2.OperationalError) could not translate host name "postgres" to address: Temporary failure in name resolution

(Background on this error at: https://sqlalche.me/e/14/e3q8)
[2024-06-27T03:39:28.154+0000] {job.py:226} ERROR - Job heartbeat failed with error. Scheduler is in unhealthy state
[2024-06-27T03:39:32.690+0000] {logging_mixin.py:188} INFO - Failed to load data into capstone-de2.***_peduli_pintar_fact.fact_volunteer_applications$20240623: 400 Provided Schema does not match Table capstone-de2:***_peduli_pintar_fact.fact_volunteer_applications$20240623. Field organization_id has changed type from INTEGER to FLOAT; reason: invalid, message: Provided Schema does not match Table capstone-de2:***_peduli_pintar_fact.fact_volunteer_applications$20240623. Field organization_id has changed type from INTEGER to FLOAT; reason: invalid, message: It looks like you are appending to an existing table with autodetect enabled. Disabling autodetect may resolve this.
[2024-06-27T03:39:32.710+0000] {logging_mixin.py:188} INFO - File 20240624_fact_volunteer_applications.csv does not match partition date 20240623, skipping.
[2024-06-27T03:39:44.347+0000] {logging_mixin.py:188} INFO - Loaded 4 rows into capstone-de2.***_peduli_pintar_fact.fact_volunteer_testimoni$20240623
[2024-06-27T03:39:44.354+0000] {logging_mixin.py:188} INFO - File 20240624_fact_volunteer_testimoni.csv does not match partition date 20240623, skipping.
[2024-06-27T03:39:48.548+0000] {logging_mixin.py:188} INFO - Failed to load data into capstone-de2.***_peduli_pintar_fact.fact_article_popular$20240623: 400 Provided Schema does not match Table capstone-de2:***_peduli_pintar_fact.fact_article_popular$20240623. Field comment_id has changed type from FLOAT to INTEGER; reason: invalid, message: Provided Schema does not match Table capstone-de2:***_peduli_pintar_fact.fact_article_popular$20240623. Field comment_id has changed type from FLOAT to INTEGER; reason: invalid, message: It looks like you are appending to an existing table with autodetect enabled. Disabling autodetect may resolve this.
[2024-06-27T03:39:48.549+0000] {logging_mixin.py:188} INFO - File 20240624_fact_article_popular.csv does not match partition date 20240623, skipping.
[2024-06-27T03:39:52.440+0000] {logging_mixin.py:188} INFO - Loaded 4 rows into capstone-de2.***_peduli_pintar_fact.fact_bookmark_fundraising$20240623
[2024-06-27T03:39:52.447+0000] {logging_mixin.py:188} INFO - File 20240624_fact_bookmark_fundraising.csv does not match partition date 20240623, skipping.
[2024-06-27T03:40:38.405+0000] {logging_mixin.py:188} INFO - Loaded 3 rows into capstone-de2.***_peduli_pintar_fact.fact_bookmark_volunteer_vacancies$20240623
[2024-06-27T03:40:38.410+0000] {logging_mixin.py:188} INFO - File 20240624_fact_bookmark_volunteer_vacancies.csv does not match partition date 20240623, skipping.
[2024-06-27T03:40:38.586+0000] {connection.py:274} WARNING - Connection schemes (type: google_cloud_platform) shall not contain '_' according to RFC3986.
[2024-06-27T03:40:38.595+0000] {base.py:84} INFO - Using connection ID 'gcp_conn_capstone_de' for task execution.
[2024-06-27T03:40:44.035+0000] {logging_mixin.py:188} INFO - Failed to load data into capstone-de2.***_peduli_pintar_dim.dim_fundraisings$20240623: 400 Some rows belong to different partitions rather than destination partition; reason: invalid, message: Some rows belong to different partitions rather than destination partition
[2024-06-27T03:40:44.036+0000] {logging_mixin.py:188} INFO - File 20240624_dim_fundraisings.csv does not match partition date 20240623, skipping.
[2024-06-27T03:40:44.037+0000] {logging_mixin.py:188} INFO - File 20240625_dim_fundraisings.csv does not match partition date 20240623, skipping.
[2024-06-27T03:40:44.039+0000] {logging_mixin.py:188} INFO - Directory dags/data_loaded/dim/dim_fundraising_categories does not exist, skipping table dim_fundraising_categories
[2024-06-27T03:40:49.017+0000] {logging_mixin.py:188} INFO - Loaded 14 rows into capstone-de2.***_peduli_pintar_dim.dim_donation_manual$20240623
[2024-06-27T03:40:49.019+0000] {logging_mixin.py:188} INFO - File 20240624_dim_donation_manual.csv does not match partition date 20240623, skipping.
[2024-06-27T03:40:49.020+0000] {logging_mixin.py:188} INFO - File 20240625_dim_donation_manual.csv does not match partition date 20240623, skipping.
[2024-06-27T03:40:52.243+0000] {logging_mixin.py:188} INFO - Loaded 0 rows into capstone-de2.***_peduli_pintar_dim.dim_organization$20240623
[2024-06-27T03:40:52.243+0000] {logging_mixin.py:188} INFO - File 20240624_dim_organization.csv does not match partition date 20240623, skipping.
[2024-06-27T03:40:52.244+0000] {logging_mixin.py:188} INFO - File 20240625_dim_organization.csv does not match partition date 20240623, skipping.
[2024-06-27T03:40:55.565+0000] {logging_mixin.py:188} INFO - Failed to load data into capstone-de2.***_peduli_pintar_dim.dim_user$20240623: 400 Some rows belong to different partitions rather than destination partition; reason: invalid, message: Some rows belong to different partitions rather than destination partition
[2024-06-27T03:40:55.567+0000] {logging_mixin.py:188} INFO - File 20240624_dim_user.csv does not match partition date 20240623, skipping.
[2024-06-27T03:40:55.568+0000] {logging_mixin.py:188} INFO - File 20240625_dim_user.csv does not match partition date 20240623, skipping.
[2024-06-27T03:41:00.009+0000] {logging_mixin.py:188} INFO - Loaded 6 rows into capstone-de2.***_peduli_pintar_dim.dim_volunteer_applictaion$20240623
[2024-06-27T03:41:00.010+0000] {logging_mixin.py:188} INFO - File 20240624_dim_volunteer_applictaion.csv does not match partition date 20240623, skipping.
[2024-06-27T03:41:03.156+0000] {logging_mixin.py:188} INFO - Failed to load data into capstone-de2.***_peduli_pintar_dim.dim_volunteer_vacancies$20240623: 400 Some rows belong to different partitions rather than destination partition; reason: invalid, message: Some rows belong to different partitions rather than destination partition
[2024-06-27T03:41:03.158+0000] {logging_mixin.py:188} INFO - File 20240624_dim_volunteer_vacancies.csv does not match partition date 20240623, skipping.
[2024-06-27T03:41:03.159+0000] {logging_mixin.py:188} INFO - File 20240625_dim_volunteer_vacancies.csv does not match partition date 20240623, skipping.
[2024-06-27T03:41:06.799+0000] {logging_mixin.py:188} INFO - Loaded 4 rows into capstone-de2.***_peduli_pintar_dim.dim_testimoni_volunteer$20240623
[2024-06-27T03:41:06.800+0000] {logging_mixin.py:188} INFO - File 20240624_dim_testimoni_volunteer.csv does not match partition date 20240623, skipping.
[2024-06-27T03:41:11.591+0000] {logging_mixin.py:188} INFO - Loaded 2 rows into capstone-de2.***_peduli_pintar_dim.dim_article$20240623
[2024-06-27T03:41:11.592+0000] {logging_mixin.py:188} INFO - File 20240624_dim_article.csv does not match partition date 20240623, skipping.
[2024-06-27T03:41:11.593+0000] {logging_mixin.py:188} INFO - File 20240625_dim_article.csv does not match partition date 20240623, skipping.
[2024-06-27T03:41:15.404+0000] {logging_mixin.py:188} INFO - Loaded 4 rows into capstone-de2.***_peduli_pintar_dim.dim_bookmark_fundraising$20240623
[2024-06-27T03:41:15.405+0000] {logging_mixin.py:188} INFO - File 20240624_dim_bookmark_fundraising.csv does not match partition date 20240623, skipping.
[2024-06-27T03:41:19.874+0000] {logging_mixin.py:188} INFO - Loaded 3 rows into capstone-de2.***_peduli_pintar_dim.dim_bookmark_volunter_vacancies$20240623
[2024-06-27T03:41:19.875+0000] {logging_mixin.py:188} INFO - File 20240624_dim_bookmark_volunter_vacancies.csv does not match partition date 20240623, skipping.
[2024-06-27T03:41:23.898+0000] {logging_mixin.py:188} INFO - Loaded 2 rows into capstone-de2.***_peduli_pintar_dim.dim_bookmark_article$20240623
[2024-06-27T03:41:23.899+0000] {logging_mixin.py:188} INFO - File 20240624_dim_bookmark_article.csv does not match partition date 20240623, skipping.
[2024-06-27T03:41:29.391+0000] {logging_mixin.py:188} INFO - Loaded 30 rows into capstone-de2.***_peduli_pintar_dim.dim_comments$20240623
[2024-06-27T03:41:34.009+0000] {logging_mixin.py:188} INFO - Loaded 19 rows into capstone-de2.***_peduli_pintar_dim.dim_like_comments$20240623
[2024-06-27T03:41:34.011+0000] {taskinstance.py:441} INFO - ::group::Post task execution logs
[2024-06-27T03:41:34.109+0000] {taskinstance.py:1206} INFO - Marking task as SUCCESS. dag_id=coba_ds_v4, task_id=load_gbq, run_id=scheduled__2024-06-23T00:00:00+00:00, execution_date=20240623T000000, start_date=20240627T033706, end_date=20240627T034134
[2024-06-27T03:41:34.220+0000] {local_task_job_runner.py:240} INFO - Task exited with return code 0
[2024-06-27T03:41:34.277+0000] {taskinstance.py:3503} INFO - 0 downstream tasks scheduled from follow-on schedule check
[2024-06-27T03:41:34.280+0000] {local_task_job_runner.py:222} INFO - ::endgroup::
