[2024-06-27T09:02:25.750+0000] {local_task_job_runner.py:120} INFO - ::group::Pre task execution logs
[2024-06-27T09:02:25.875+0000] {taskinstance.py:2076} INFO - Dependencies all met for dep_context=non-requeueable deps ti=<TaskInstance: peduli_pintar_etl_dags_v3.load_gbq scheduled__2024-06-23T00:00:00+00:00 [queued]>
[2024-06-27T09:02:25.913+0000] {taskinstance.py:2076} INFO - Dependencies all met for dep_context=requeueable deps ti=<TaskInstance: peduli_pintar_etl_dags_v3.load_gbq scheduled__2024-06-23T00:00:00+00:00 [queued]>
[2024-06-27T09:02:25.915+0000] {taskinstance.py:2306} INFO - Starting attempt 1 of 5
[2024-06-27T09:02:25.972+0000] {taskinstance.py:2330} INFO - Executing <Task(LoadGoogleBigQuery): load_gbq> on 2024-06-23 00:00:00+00:00
[2024-06-27T09:02:26.003+0000] {warnings.py:112} WARNING - /home/***/.local/lib/python3.12/site-packages/***/task/task_runner/standard_task_runner.py:61: DeprecationWarning: This process (pid=337) is multi-threaded, use of fork() may lead to deadlocks in the child.
  pid = os.fork()

[2024-06-27T09:02:26.008+0000] {standard_task_runner.py:63} INFO - Started process 349 to run task
[2024-06-27T09:02:26.011+0000] {standard_task_runner.py:90} INFO - Running: ['***', 'tasks', 'run', 'peduli_pintar_etl_dags_v3', 'load_gbq', 'scheduled__2024-06-23T00:00:00+00:00', '--job-id', '54', '--raw', '--subdir', 'DAGS_FOLDER/etl_dags.py', '--cfg-path', '/tmp/tmp6kojg2n3']
[2024-06-27T09:02:26.033+0000] {standard_task_runner.py:91} INFO - Job 54: Subtask load_gbq
[2024-06-27T09:02:26.167+0000] {task_command.py:426} INFO - Running <TaskInstance: peduli_pintar_etl_dags_v3.load_gbq scheduled__2024-06-23T00:00:00+00:00 [running]> on host 3dad981482d5
[2024-06-27T09:02:26.326+0000] {taskinstance.py:2648} INFO - Exporting env vars: AIRFLOW_CTX_DAG_OWNER='Kelompok 5 Capstone DE' AIRFLOW_CTX_DAG_ID='peduli_pintar_etl_dags_v3' AIRFLOW_CTX_TASK_ID='load_gbq' AIRFLOW_CTX_EXECUTION_DATE='2024-06-23T00:00:00+00:00' AIRFLOW_CTX_TRY_NUMBER='1' AIRFLOW_CTX_DAG_RUN_ID='scheduled__2024-06-23T00:00:00+00:00'
[2024-06-27T09:02:26.328+0000] {taskinstance.py:430} INFO - ::endgroup::
[2024-06-27T09:02:26.376+0000] {connection.py:274} WARNING - Connection schemes (type: google_cloud_platform) shall not contain '_' according to RFC3986.
[2024-06-27T09:02:26.381+0000] {base.py:84} INFO - Using connection ID 'gcp_conn_capstone_de' for task execution.
[2024-06-27T09:02:31.251+0000] {logging_mixin.py:188} INFO - Loaded 1 rows into capstone-de2.***_peduli_pintar_fact.fact_donation_transaction$20240623
[2024-06-27T09:02:31.253+0000] {logging_mixin.py:188} INFO - File 20240624_fact_donation_transaction.csv does not match partition date 20240623, skipping.
[2024-06-27T09:02:31.254+0000] {logging_mixin.py:188} INFO - File 20240625_fact_donation_transaction.csv does not match partition date 20240623, skipping.
[2024-06-27T09:02:36.110+0000] {logging_mixin.py:188} INFO - Loaded 6 rows into capstone-de2.***_peduli_pintar_fact.fact_volunteer_applications$20240623
[2024-06-27T09:02:36.111+0000] {logging_mixin.py:188} INFO - File 20240624_fact_volunteer_applications.csv does not match partition date 20240623, skipping.
[2024-06-27T09:02:36.111+0000] {logging_mixin.py:188} INFO - File 20240626_fact_volunteer_applications.csv does not match partition date 20240623, skipping.
[2024-06-27T09:02:41.978+0000] {logging_mixin.py:188} INFO - Loaded 4 rows into capstone-de2.***_peduli_pintar_fact.fact_volunteer_testimoni$20240623
[2024-06-27T09:02:41.979+0000] {logging_mixin.py:188} INFO - File 20240624_fact_volunteer_testimoni.csv does not match partition date 20240623, skipping.
[2024-06-27T09:02:43.647+0000] {logging_mixin.py:188} INFO - Failed to load data into capstone-de2.***_peduli_pintar_fact.fact_article_popular$20240623: 400 Provided Schema does not match Table capstone-de2:***_peduli_pintar_fact.fact_article_popular$20240623. Field comment_id has changed type from FLOAT to INTEGER; reason: invalid, message: Provided Schema does not match Table capstone-de2:***_peduli_pintar_fact.fact_article_popular$20240623. Field comment_id has changed type from FLOAT to INTEGER
[2024-06-27T09:02:43.650+0000] {logging_mixin.py:188} INFO - File 20240624_fact_article_popular.csv does not match partition date 20240623, skipping.
[2024-06-27T09:02:47.889+0000] {logging_mixin.py:188} INFO - Loaded 4 rows into capstone-de2.***_peduli_pintar_fact.fact_bookmark_fundraising$20240623
[2024-06-27T09:02:47.890+0000] {logging_mixin.py:188} INFO - File 20240624_fact_bookmark_fundraising.csv does not match partition date 20240623, skipping.
[2024-06-27T09:02:52.245+0000] {logging_mixin.py:188} INFO - Loaded 3 rows into capstone-de2.***_peduli_pintar_fact.fact_bookmark_volunteer_vacancies$20240623
[2024-06-27T09:02:52.246+0000] {logging_mixin.py:188} INFO - File 20240624_fact_bookmark_volunteer_vacancies.csv does not match partition date 20240623, skipping.
[2024-06-27T09:02:52.247+0000] {logging_mixin.py:188} INFO - File 20240626_fact_bookmark_volunteer_vacancies.csv does not match partition date 20240623, skipping.
[2024-06-27T09:02:52.324+0000] {connection.py:274} WARNING - Connection schemes (type: google_cloud_platform) shall not contain '_' according to RFC3986.
[2024-06-27T09:02:52.329+0000] {base.py:84} INFO - Using connection ID 'gcp_conn_capstone_de' for task execution.
[2024-06-27T09:02:56.888+0000] {logging_mixin.py:188} INFO - Failed to load data into capstone-de2.***_peduli_pintar_dim.dim_fundraisings$20240623: 400 Some rows belong to different partitions rather than destination partition; reason: invalid, message: Some rows belong to different partitions rather than destination partition
[2024-06-27T09:02:56.889+0000] {logging_mixin.py:188} INFO - File 20240624_dim_fundraisings.csv does not match partition date 20240623, skipping.
[2024-06-27T09:02:56.890+0000] {logging_mixin.py:188} INFO - File 20240625_dim_fundraisings.csv does not match partition date 20240623, skipping.
[2024-06-27T09:02:56.892+0000] {logging_mixin.py:188} INFO - Directory dags/data_loaded/dim/dim_fundraising_categories does not exist, skipping table dim_fundraising_categories
[2024-06-27T09:03:01.040+0000] {logging_mixin.py:188} INFO - Loaded 14 rows into capstone-de2.***_peduli_pintar_dim.dim_donation_manual$20240623
[2024-06-27T09:03:01.041+0000] {logging_mixin.py:188} INFO - File 20240624_dim_donation_manual.csv does not match partition date 20240623, skipping.
[2024-06-27T09:03:01.041+0000] {logging_mixin.py:188} INFO - File 20240625_dim_donation_manual.csv does not match partition date 20240623, skipping.
[2024-06-27T09:03:05.449+0000] {logging_mixin.py:188} INFO - Loaded 0 rows into capstone-de2.***_peduli_pintar_dim.dim_organization$20240623
[2024-06-27T09:03:05.450+0000] {logging_mixin.py:188} INFO - File 20240624_dim_organization.csv does not match partition date 20240623, skipping.
[2024-06-27T09:03:05.450+0000] {logging_mixin.py:188} INFO - File 20240625_dim_organization.csv does not match partition date 20240623, skipping.
[2024-06-27T09:03:08.862+0000] {logging_mixin.py:188} INFO - Failed to load data into capstone-de2.***_peduli_pintar_dim.dim_user$20240623: 400 Some rows belong to different partitions rather than destination partition; reason: invalid, message: Some rows belong to different partitions rather than destination partition
[2024-06-27T09:03:08.864+0000] {logging_mixin.py:188} INFO - File 20240624_dim_user.csv does not match partition date 20240623, skipping.
[2024-06-27T09:03:08.865+0000] {logging_mixin.py:188} INFO - File 20240625_dim_user.csv does not match partition date 20240623, skipping.
[2024-06-27T09:03:08.866+0000] {logging_mixin.py:188} INFO - File 20240626_dim_user.csv does not match partition date 20240623, skipping.
[2024-06-27T09:03:38.367+0000] {logging_mixin.py:188} INFO - Loaded 6 rows into capstone-de2.***_peduli_pintar_dim.dim_volunteer_applictaion$20240623
[2024-06-27T09:03:38.423+0000] {logging_mixin.py:188} INFO - File 20240624_dim_volunteer_applictaion.csv does not match partition date 20240623, skipping.
[2024-06-27T09:03:38.427+0000] {logging_mixin.py:188} INFO - File 20240626_dim_volunteer_applictaion.csv does not match partition date 20240623, skipping.
[2024-06-27T09:03:42.847+0000] {logging_mixin.py:188} INFO - Failed to load data into capstone-de2.***_peduli_pintar_dim.dim_volunteer_vacancies$20240623: 400 Some rows belong to different partitions rather than destination partition; reason: invalid, message: Some rows belong to different partitions rather than destination partition
[2024-06-27T09:03:42.904+0000] {logging_mixin.py:188} INFO - File 20240624_dim_volunteer_vacancies.csv does not match partition date 20240623, skipping.
[2024-06-27T09:03:42.990+0000] {logging_mixin.py:188} INFO - File 20240625_dim_volunteer_vacancies.csv does not match partition date 20240623, skipping.
[2024-06-27T09:03:42.999+0000] {logging_mixin.py:188} INFO - File 20240626_dim_volunteer_vacancies.csv does not match partition date 20240623, skipping.
[2024-06-27T09:03:59.352+0000] {logging_mixin.py:188} INFO - Loaded 4 rows into capstone-de2.***_peduli_pintar_dim.dim_testimoni_volunteer$20240623
[2024-06-27T09:03:59.360+0000] {logging_mixin.py:188} INFO - File 20240624_dim_testimoni_volunteer.csv does not match partition date 20240623, skipping.
[2024-06-27T09:04:04.476+0000] {logging_mixin.py:188} INFO - Loaded 2 rows into capstone-de2.***_peduli_pintar_dim.dim_article$20240623
[2024-06-27T09:04:04.478+0000] {logging_mixin.py:188} INFO - File 20240624_dim_article.csv does not match partition date 20240623, skipping.
[2024-06-27T09:04:04.479+0000] {logging_mixin.py:188} INFO - File 20240625_dim_article.csv does not match partition date 20240623, skipping.
[2024-06-27T09:04:08.357+0000] {logging_mixin.py:188} INFO - Loaded 4 rows into capstone-de2.***_peduli_pintar_dim.dim_bookmark_fundraising$20240623
[2024-06-27T09:04:08.358+0000] {logging_mixin.py:188} INFO - File 20240624_dim_bookmark_fundraising.csv does not match partition date 20240623, skipping.
[2024-06-27T09:04:12.769+0000] {logging_mixin.py:188} INFO - Loaded 3 rows into capstone-de2.***_peduli_pintar_dim.dim_bookmark_volunter_vacancies$20240623
[2024-06-27T09:04:12.774+0000] {logging_mixin.py:188} INFO - File 20240624_dim_bookmark_volunter_vacancies.csv does not match partition date 20240623, skipping.
[2024-06-27T09:04:12.776+0000] {logging_mixin.py:188} INFO - File 20240626_dim_bookmark_volunter_vacancies.csv does not match partition date 20240623, skipping.
[2024-06-27T09:04:16.886+0000] {logging_mixin.py:188} INFO - Loaded 2 rows into capstone-de2.***_peduli_pintar_dim.dim_bookmark_article$20240623
[2024-06-27T09:04:16.889+0000] {logging_mixin.py:188} INFO - File 20240624_dim_bookmark_article.csv does not match partition date 20240623, skipping.
[2024-06-27T09:04:21.085+0000] {logging_mixin.py:188} INFO - Loaded 30 rows into capstone-de2.***_peduli_pintar_dim.dim_comments$20240623
[2024-06-27T09:04:24.825+0000] {logging_mixin.py:188} INFO - Loaded 19 rows into capstone-de2.***_peduli_pintar_dim.dim_like_comments$20240623
[2024-06-27T09:04:24.837+0000] {taskinstance.py:441} INFO - ::group::Post task execution logs
[2024-06-27T09:04:38.484+0000] {taskinstance.py:2905} ERROR - Task failed with exception
Traceback (most recent call last):
  File "/home/airflow/.local/lib/python3.12/site-packages/sqlalchemy/engine/base.py", line 3371, in _wrap_pool_connect
    return fn()
           ^^^^
  File "/home/airflow/.local/lib/python3.12/site-packages/sqlalchemy/pool/base.py", line 327, in connect
    return _ConnectionFairy._checkout(self)
           ^^^^^^^^^^^^^^^^^^^^^^^^^^^^^^^^
  File "/home/airflow/.local/lib/python3.12/site-packages/sqlalchemy/pool/base.py", line 894, in _checkout
    fairy = _ConnectionRecord.checkout(pool)
            ^^^^^^^^^^^^^^^^^^^^^^^^^^^^^^^^
  File "/home/airflow/.local/lib/python3.12/site-packages/sqlalchemy/pool/base.py", line 493, in checkout
    rec = pool._do_get()
          ^^^^^^^^^^^^^^
  File "/home/airflow/.local/lib/python3.12/site-packages/sqlalchemy/pool/impl.py", line 256, in _do_get
    return self._create_connection()
           ^^^^^^^^^^^^^^^^^^^^^^^^^
  File "/home/airflow/.local/lib/python3.12/site-packages/sqlalchemy/pool/base.py", line 273, in _create_connection
    return _ConnectionRecord(self)
           ^^^^^^^^^^^^^^^^^^^^^^^
  File "/home/airflow/.local/lib/python3.12/site-packages/sqlalchemy/pool/base.py", line 388, in __init__
    self.__connect()
  File "/home/airflow/.local/lib/python3.12/site-packages/sqlalchemy/pool/base.py", line 690, in __connect
    with util.safe_reraise():
  File "/home/airflow/.local/lib/python3.12/site-packages/sqlalchemy/util/langhelpers.py", line 70, in __exit__
    compat.raise_(
  File "/home/airflow/.local/lib/python3.12/site-packages/sqlalchemy/util/compat.py", line 211, in raise_
    raise exception
  File "/home/airflow/.local/lib/python3.12/site-packages/sqlalchemy/pool/base.py", line 686, in __connect
    self.dbapi_connection = connection = pool._invoke_creator(self)
                                         ^^^^^^^^^^^^^^^^^^^^^^^^^^
  File "/home/airflow/.local/lib/python3.12/site-packages/sqlalchemy/engine/create.py", line 574, in connect
    return dialect.connect(*cargs, **cparams)
           ^^^^^^^^^^^^^^^^^^^^^^^^^^^^^^^^^^
  File "/home/airflow/.local/lib/python3.12/site-packages/sqlalchemy/engine/default.py", line 598, in connect
    return self.dbapi.connect(*cargs, **cparams)
           ^^^^^^^^^^^^^^^^^^^^^^^^^^^^^^^^^^^^^
  File "/home/airflow/.local/lib/python3.12/site-packages/psycopg2/__init__.py", line 122, in connect
    conn = _connect(dsn, connection_factory=connection_factory, **kwasync)
           ^^^^^^^^^^^^^^^^^^^^^^^^^^^^^^^^^^^^^^^^^^^^^^^^^^^^^^^^^^^^^^^
psycopg2.OperationalError: could not translate host name "postgres" to address: Temporary failure in name resolution


The above exception was the direct cause of the following exception:

Traceback (most recent call last):
  File "/home/airflow/.local/lib/python3.12/site-packages/airflow/models/taskinstance.py", line 486, in _execute_task
    task_instance.xcom_push(key=XCOM_RETURN_KEY, value=xcom_value, session=session)
  File "/home/airflow/.local/lib/python3.12/site-packages/airflow/utils/session.py", line 76, in wrapper
    return func(*args, **kwargs)
           ^^^^^^^^^^^^^^^^^^^^^
  File "/home/airflow/.local/lib/python3.12/site-packages/airflow/models/taskinstance.py", line 3197, in xcom_push
    XCom.set(
  File "/home/airflow/.local/lib/python3.12/site-packages/airflow/utils/session.py", line 76, in wrapper
    return func(*args, **kwargs)
           ^^^^^^^^^^^^^^^^^^^^^
  File "/home/airflow/.local/lib/python3.12/site-packages/airflow/models/xcom.py", line 221, in set
    dag_run_id = session.query(DagRun.id).filter_by(dag_id=dag_id, run_id=run_id).scalar()
                 ^^^^^^^^^^^^^^^^^^^^^^^^^^^^^^^^^^^^^^^^^^^^^^^^^^^^^^^^^^^^^^^^^^^^^^^^^
  File "/home/airflow/.local/lib/python3.12/site-packages/sqlalchemy/orm/query.py", line 2893, in scalar
    ret = self.one()
          ^^^^^^^^^^
  File "/home/airflow/.local/lib/python3.12/site-packages/sqlalchemy/orm/query.py", line 2870, in one
    return self._iter().one()
           ^^^^^^^^^^^^
  File "/home/airflow/.local/lib/python3.12/site-packages/sqlalchemy/orm/query.py", line 2916, in _iter
    result = self.session.execute(
             ^^^^^^^^^^^^^^^^^^^^^
  File "/home/airflow/.local/lib/python3.12/site-packages/sqlalchemy/orm/session.py", line 1716, in execute
    conn = self._connection_for_bind(bind)
           ^^^^^^^^^^^^^^^^^^^^^^^^^^^^^^^
  File "/home/airflow/.local/lib/python3.12/site-packages/sqlalchemy/orm/session.py", line 1555, in _connection_for_bind
    return self._transaction._connection_for_bind(
           ^^^^^^^^^^^^^^^^^^^^^^^^^^^^^^^^^^^^^^^
  File "/home/airflow/.local/lib/python3.12/site-packages/sqlalchemy/orm/session.py", line 750, in _connection_for_bind
    conn = bind.connect()
           ^^^^^^^^^^^^^^
  File "/home/airflow/.local/lib/python3.12/site-packages/sqlalchemy/future/engine.py", line 412, in connect
    return super(Engine, self).connect()
           ^^^^^^^^^^^^^^^^^^^^^^^^^^^^^
  File "/home/airflow/.local/lib/python3.12/site-packages/sqlalchemy/engine/base.py", line 3325, in connect
    return self._connection_cls(self, close_with_result=close_with_result)
           ^^^^^^^^^^^^^^^^^^^^^^^^^^^^^^^^^^^^^^^^^^^^^^^^^^^^^^^^^^^^^^^
  File "/home/airflow/.local/lib/python3.12/site-packages/sqlalchemy/engine/base.py", line 96, in __init__
    else engine.raw_connection()
         ^^^^^^^^^^^^^^^^^^^^^^^
  File "/home/airflow/.local/lib/python3.12/site-packages/sqlalchemy/engine/base.py", line 3404, in raw_connection
    return self._wrap_pool_connect(self.pool.connect, _connection)
           ^^^^^^^^^^^^^^^^^^^^^^^^^^^^^^^^^^^^^^^^^^^^^^^^^^^^^^^
  File "/home/airflow/.local/lib/python3.12/site-packages/sqlalchemy/engine/base.py", line 3374, in _wrap_pool_connect
    Connection._handle_dbapi_exception_noconnection(
  File "/home/airflow/.local/lib/python3.12/site-packages/sqlalchemy/engine/base.py", line 2208, in _handle_dbapi_exception_noconnection
    util.raise_(
  File "/home/airflow/.local/lib/python3.12/site-packages/sqlalchemy/util/compat.py", line 211, in raise_
    raise exception
  File "/home/airflow/.local/lib/python3.12/site-packages/sqlalchemy/engine/base.py", line 3371, in _wrap_pool_connect
    return fn()
           ^^^^
  File "/home/airflow/.local/lib/python3.12/site-packages/sqlalchemy/pool/base.py", line 327, in connect
    return _ConnectionFairy._checkout(self)
           ^^^^^^^^^^^^^^^^^^^^^^^^^^^^^^^^
  File "/home/airflow/.local/lib/python3.12/site-packages/sqlalchemy/pool/base.py", line 894, in _checkout
    fairy = _ConnectionRecord.checkout(pool)
            ^^^^^^^^^^^^^^^^^^^^^^^^^^^^^^^^
  File "/home/airflow/.local/lib/python3.12/site-packages/sqlalchemy/pool/base.py", line 493, in checkout
    rec = pool._do_get()
          ^^^^^^^^^^^^^^
  File "/home/airflow/.local/lib/python3.12/site-packages/sqlalchemy/pool/impl.py", line 256, in _do_get
    return self._create_connection()
           ^^^^^^^^^^^^^^^^^^^^^^^^^
  File "/home/airflow/.local/lib/python3.12/site-packages/sqlalchemy/pool/base.py", line 273, in _create_connection
    return _ConnectionRecord(self)
           ^^^^^^^^^^^^^^^^^^^^^^^
  File "/home/airflow/.local/lib/python3.12/site-packages/sqlalchemy/pool/base.py", line 388, in __init__
    self.__connect()
  File "/home/airflow/.local/lib/python3.12/site-packages/sqlalchemy/pool/base.py", line 690, in __connect
    with util.safe_reraise():
  File "/home/airflow/.local/lib/python3.12/site-packages/sqlalchemy/util/langhelpers.py", line 70, in __exit__
    compat.raise_(
  File "/home/airflow/.local/lib/python3.12/site-packages/sqlalchemy/util/compat.py", line 211, in raise_
    raise exception
  File "/home/airflow/.local/lib/python3.12/site-packages/sqlalchemy/pool/base.py", line 686, in __connect
    self.dbapi_connection = connection = pool._invoke_creator(self)
                                         ^^^^^^^^^^^^^^^^^^^^^^^^^^
  File "/home/airflow/.local/lib/python3.12/site-packages/sqlalchemy/engine/create.py", line 574, in connect
    return dialect.connect(*cargs, **cparams)
           ^^^^^^^^^^^^^^^^^^^^^^^^^^^^^^^^^^
  File "/home/airflow/.local/lib/python3.12/site-packages/sqlalchemy/engine/default.py", line 598, in connect
    return self.dbapi.connect(*cargs, **cparams)
           ^^^^^^^^^^^^^^^^^^^^^^^^^^^^^^^^^^^^^
  File "/home/airflow/.local/lib/python3.12/site-packages/psycopg2/__init__.py", line 122, in connect
    conn = _connect(dsn, connection_factory=connection_factory, **kwasync)
           ^^^^^^^^^^^^^^^^^^^^^^^^^^^^^^^^^^^^^^^^^^^^^^^^^^^^^^^^^^^^^^^
sqlalchemy.exc.OperationalError: (psycopg2.OperationalError) could not translate host name "postgres" to address: Temporary failure in name resolution

(Background on this error at: https://sqlalche.me/e/14/e3q8)
[2024-06-27T09:05:38.739+0000] {job.py:218} ERROR - Job heartbeat got an exception
Traceback (most recent call last):
  File "/home/airflow/.local/lib/python3.12/site-packages/sqlalchemy/engine/base.py", line 3371, in _wrap_pool_connect
    return fn()
           ^^^^
  File "/home/airflow/.local/lib/python3.12/site-packages/sqlalchemy/pool/base.py", line 327, in connect
    return _ConnectionFairy._checkout(self)
           ^^^^^^^^^^^^^^^^^^^^^^^^^^^^^^^^
  File "/home/airflow/.local/lib/python3.12/site-packages/sqlalchemy/pool/base.py", line 894, in _checkout
    fairy = _ConnectionRecord.checkout(pool)
            ^^^^^^^^^^^^^^^^^^^^^^^^^^^^^^^^
  File "/home/airflow/.local/lib/python3.12/site-packages/sqlalchemy/pool/base.py", line 493, in checkout
    rec = pool._do_get()
          ^^^^^^^^^^^^^^
  File "/home/airflow/.local/lib/python3.12/site-packages/sqlalchemy/pool/impl.py", line 256, in _do_get
    return self._create_connection()
           ^^^^^^^^^^^^^^^^^^^^^^^^^
  File "/home/airflow/.local/lib/python3.12/site-packages/sqlalchemy/pool/base.py", line 273, in _create_connection
    return _ConnectionRecord(self)
           ^^^^^^^^^^^^^^^^^^^^^^^
  File "/home/airflow/.local/lib/python3.12/site-packages/sqlalchemy/pool/base.py", line 388, in __init__
    self.__connect()
  File "/home/airflow/.local/lib/python3.12/site-packages/sqlalchemy/pool/base.py", line 690, in __connect
    with util.safe_reraise():
  File "/home/airflow/.local/lib/python3.12/site-packages/sqlalchemy/util/langhelpers.py", line 70, in __exit__
    compat.raise_(
  File "/home/airflow/.local/lib/python3.12/site-packages/sqlalchemy/util/compat.py", line 211, in raise_
    raise exception
  File "/home/airflow/.local/lib/python3.12/site-packages/sqlalchemy/pool/base.py", line 686, in __connect
    self.dbapi_connection = connection = pool._invoke_creator(self)
                                         ^^^^^^^^^^^^^^^^^^^^^^^^^^
  File "/home/airflow/.local/lib/python3.12/site-packages/sqlalchemy/engine/create.py", line 574, in connect
    return dialect.connect(*cargs, **cparams)
           ^^^^^^^^^^^^^^^^^^^^^^^^^^^^^^^^^^
  File "/home/airflow/.local/lib/python3.12/site-packages/sqlalchemy/engine/default.py", line 598, in connect
    return self.dbapi.connect(*cargs, **cparams)
           ^^^^^^^^^^^^^^^^^^^^^^^^^^^^^^^^^^^^^
  File "/home/airflow/.local/lib/python3.12/site-packages/psycopg2/__init__.py", line 122, in connect
    conn = _connect(dsn, connection_factory=connection_factory, **kwasync)
           ^^^^^^^^^^^^^^^^^^^^^^^^^^^^^^^^^^^^^^^^^^^^^^^^^^^^^^^^^^^^^^^
psycopg2.OperationalError: could not translate host name "postgres" to address: Temporary failure in name resolution


The above exception was the direct cause of the following exception:

Traceback (most recent call last):
  File "/home/airflow/.local/lib/python3.12/site-packages/airflow/jobs/job.py", line 192, in heartbeat
    self._merge_from(Job._fetch_from_db(self, session))
                     ^^^^^^^^^^^^^^^^^^^^^^^^^^^^^^^^^
  File "/home/airflow/.local/lib/python3.12/site-packages/airflow/api_internal/internal_api_call.py", line 115, in wrapper
    return func(*args, **kwargs)
           ^^^^^^^^^^^^^^^^^^^^^
  File "/home/airflow/.local/lib/python3.12/site-packages/airflow/utils/session.py", line 76, in wrapper
    return func(*args, **kwargs)
           ^^^^^^^^^^^^^^^^^^^^^
  File "/home/airflow/.local/lib/python3.12/site-packages/airflow/utils/retries.py", line 89, in wrapped_function
    for attempt in run_with_db_retries(max_retries=retries, logger=logger, **retry_kwargs):
  File "/home/airflow/.local/lib/python3.12/site-packages/tenacity/__init__.py", line 435, in __iter__
    do = self.iter(retry_state=retry_state)
         ^^^^^^^^^^^^^^^^^^^^^^^^^^^^^^^^^^
  File "/home/airflow/.local/lib/python3.12/site-packages/tenacity/__init__.py", line 368, in iter
    result = action(retry_state)
             ^^^^^^^^^^^^^^^^^^^
  File "/home/airflow/.local/lib/python3.12/site-packages/tenacity/__init__.py", line 410, in exc_check
    raise retry_exc.reraise()
          ^^^^^^^^^^^^^^^^^^^
  File "/home/airflow/.local/lib/python3.12/site-packages/tenacity/__init__.py", line 183, in reraise
    raise self.last_attempt.result()
          ^^^^^^^^^^^^^^^^^^^^^^^^^^
  File "/usr/local/lib/python3.12/concurrent/futures/_base.py", line 449, in result
    return self.__get_result()
           ^^^^^^^^^^^^^^^^^^^
  File "/usr/local/lib/python3.12/concurrent/futures/_base.py", line 401, in __get_result
    raise self._exception
  File "/home/airflow/.local/lib/python3.12/site-packages/airflow/utils/retries.py", line 98, in wrapped_function
    return func(*args, **kwargs)
           ^^^^^^^^^^^^^^^^^^^^^
  File "/home/airflow/.local/lib/python3.12/site-packages/airflow/jobs/job.py", line 316, in _fetch_from_db
    session.merge(job)
  File "/home/airflow/.local/lib/python3.12/site-packages/sqlalchemy/orm/session.py", line 3056, in merge
    return self._merge(
           ^^^^^^^^^^^^
  File "/home/airflow/.local/lib/python3.12/site-packages/sqlalchemy/orm/session.py", line 3136, in _merge
    merged = self.get(
             ^^^^^^^^^
  File "/home/airflow/.local/lib/python3.12/site-packages/sqlalchemy/orm/session.py", line 2853, in get
    return self._get_impl(
           ^^^^^^^^^^^^^^^
  File "/home/airflow/.local/lib/python3.12/site-packages/sqlalchemy/orm/session.py", line 2975, in _get_impl
    return db_load_fn(
           ^^^^^^^^^^^
  File "/home/airflow/.local/lib/python3.12/site-packages/sqlalchemy/orm/loading.py", line 530, in load_on_pk_identity
    session.execute(
  File "/home/airflow/.local/lib/python3.12/site-packages/sqlalchemy/orm/session.py", line 1716, in execute
    conn = self._connection_for_bind(bind)
           ^^^^^^^^^^^^^^^^^^^^^^^^^^^^^^^
  File "/home/airflow/.local/lib/python3.12/site-packages/sqlalchemy/orm/session.py", line 1555, in _connection_for_bind
    return self._transaction._connection_for_bind(
           ^^^^^^^^^^^^^^^^^^^^^^^^^^^^^^^^^^^^^^^
  File "/home/airflow/.local/lib/python3.12/site-packages/sqlalchemy/orm/session.py", line 750, in _connection_for_bind
    conn = bind.connect()
           ^^^^^^^^^^^^^^
  File "/home/airflow/.local/lib/python3.12/site-packages/sqlalchemy/future/engine.py", line 412, in connect
    return super(Engine, self).connect()
           ^^^^^^^^^^^^^^^^^^^^^^^^^^^^^
  File "/home/airflow/.local/lib/python3.12/site-packages/sqlalchemy/engine/base.py", line 3325, in connect
    return self._connection_cls(self, close_with_result=close_with_result)
           ^^^^^^^^^^^^^^^^^^^^^^^^^^^^^^^^^^^^^^^^^^^^^^^^^^^^^^^^^^^^^^^
  File "/home/airflow/.local/lib/python3.12/site-packages/sqlalchemy/engine/base.py", line 96, in __init__
    else engine.raw_connection()
         ^^^^^^^^^^^^^^^^^^^^^^^
  File "/home/airflow/.local/lib/python3.12/site-packages/sqlalchemy/engine/base.py", line 3404, in raw_connection
    return self._wrap_pool_connect(self.pool.connect, _connection)
           ^^^^^^^^^^^^^^^^^^^^^^^^^^^^^^^^^^^^^^^^^^^^^^^^^^^^^^^
  File "/home/airflow/.local/lib/python3.12/site-packages/sqlalchemy/engine/base.py", line 3374, in _wrap_pool_connect
    Connection._handle_dbapi_exception_noconnection(
  File "/home/airflow/.local/lib/python3.12/site-packages/sqlalchemy/engine/base.py", line 2208, in _handle_dbapi_exception_noconnection
    util.raise_(
  File "/home/airflow/.local/lib/python3.12/site-packages/sqlalchemy/util/compat.py", line 211, in raise_
    raise exception
  File "/home/airflow/.local/lib/python3.12/site-packages/sqlalchemy/engine/base.py", line 3371, in _wrap_pool_connect
    return fn()
           ^^^^
  File "/home/airflow/.local/lib/python3.12/site-packages/sqlalchemy/pool/base.py", line 327, in connect
    return _ConnectionFairy._checkout(self)
           ^^^^^^^^^^^^^^^^^^^^^^^^^^^^^^^^
  File "/home/airflow/.local/lib/python3.12/site-packages/sqlalchemy/pool/base.py", line 894, in _checkout
    fairy = _ConnectionRecord.checkout(pool)
            ^^^^^^^^^^^^^^^^^^^^^^^^^^^^^^^^
  File "/home/airflow/.local/lib/python3.12/site-packages/sqlalchemy/pool/base.py", line 493, in checkout
    rec = pool._do_get()
          ^^^^^^^^^^^^^^
  File "/home/airflow/.local/lib/python3.12/site-packages/sqlalchemy/pool/impl.py", line 256, in _do_get
    return self._create_connection()
           ^^^^^^^^^^^^^^^^^^^^^^^^^
  File "/home/airflow/.local/lib/python3.12/site-packages/sqlalchemy/pool/base.py", line 273, in _create_connection
    return _ConnectionRecord(self)
           ^^^^^^^^^^^^^^^^^^^^^^^
  File "/home/airflow/.local/lib/python3.12/site-packages/sqlalchemy/pool/base.py", line 388, in __init__
    self.__connect()
  File "/home/airflow/.local/lib/python3.12/site-packages/sqlalchemy/pool/base.py", line 690, in __connect
    with util.safe_reraise():
  File "/home/airflow/.local/lib/python3.12/site-packages/sqlalchemy/util/langhelpers.py", line 70, in __exit__
    compat.raise_(
  File "/home/airflow/.local/lib/python3.12/site-packages/sqlalchemy/util/compat.py", line 211, in raise_
    raise exception
  File "/home/airflow/.local/lib/python3.12/site-packages/sqlalchemy/pool/base.py", line 686, in __connect
    self.dbapi_connection = connection = pool._invoke_creator(self)
                                         ^^^^^^^^^^^^^^^^^^^^^^^^^^
  File "/home/airflow/.local/lib/python3.12/site-packages/sqlalchemy/engine/create.py", line 574, in connect
    return dialect.connect(*cargs, **cparams)
           ^^^^^^^^^^^^^^^^^^^^^^^^^^^^^^^^^^
  File "/home/airflow/.local/lib/python3.12/site-packages/sqlalchemy/engine/default.py", line 598, in connect
    return self.dbapi.connect(*cargs, **cparams)
           ^^^^^^^^^^^^^^^^^^^^^^^^^^^^^^^^^^^^^
  File "/home/airflow/.local/lib/python3.12/site-packages/psycopg2/__init__.py", line 122, in connect
    conn = _connect(dsn, connection_factory=connection_factory, **kwasync)
           ^^^^^^^^^^^^^^^^^^^^^^^^^^^^^^^^^^^^^^^^^^^^^^^^^^^^^^^^^^^^^^^
sqlalchemy.exc.OperationalError: (psycopg2.OperationalError) could not translate host name "postgres" to address: Temporary failure in name resolution

(Background on this error at: https://sqlalche.me/e/14/e3q8)
[2024-06-27T09:05:40.490+0000] {job.py:226} ERROR - Job heartbeat failed with error. Scheduler is in unhealthy state
[2024-06-27T09:05:50.256+0000] {standard_task_runner.py:110} ERROR - Failed to execute job 54 for task load_gbq ((psycopg2.OperationalError) could not translate host name "postgres" to address: Temporary failure in name resolution

(Background on this error at: https://sqlalche.me/e/14/e3q8); 349)
[2024-06-27T09:06:19.842+0000] {job.py:226} ERROR - Job heartbeat failed with error. Scheduler is in unhealthy state
[2024-06-27T09:06:27.184+0000] {local_task_job_runner.py:240} INFO - Task exited with return code 1
[2024-06-27T09:06:35.861+0000] {taskinstance.py:3503} INFO - 0 downstream tasks scheduled from follow-on schedule check
[2024-06-27T09:06:35.891+0000] {local_task_job_runner.py:222} INFO - ::endgroup::
